<sdf version='1.6'>
  <world name='default'>
    <light name='sun' type='directional'>
      <cast_shadows>1</cast_shadows>
      <pose frame=''>0 0 10 0 -0 0</pose>
      <diffuse>0.8 0.8 0.8 1</diffuse>
      <specular>0.2 0.2 0.2 1</specular>
      <attenuation>
        <range>1000</range>
        <constant>0.9</constant>
        <linear>0.01</linear>
        <quadratic>0.001</quadratic>
      </attenuation>
      <direction>-0.5 0.1 -0.9</direction>
    </light>
    <physics name='dart_2ms' default='0' type='dart'>
      <max_step_size>0.002</max_step_size>
      <real_time_factor>1</real_time_factor>
      <real_time_update_rate>500</real_time_update_rate>
      <dart>
        <solver>
          <solver_type>pgs</solver_type>
        </solver>
      </dart>
    </physics>
    <model name='ground_plane'>
      <static>1</static>
      <link name='link'>
        <collision name='collision'>
          <geometry>
            <plane>
              <normal>0 0 1</normal>
              <size>100 100</size>
            </plane>
          </geometry>
          <surface>
            <contact>
              <collide_bitmask>65535</collide_bitmask>
            </contact>
            <friction>
              <ode>
                <mu>100</mu>
                <mu2>50</mu2>
              </ode>
            </friction>
          </surface>
          <max_contacts>10</max_contacts>
        </collision>
        <visual name='visual'>
          <cast_shadows>0</cast_shadows>
          <geometry>
            <plane>
              <normal>0 0 1</normal>
              <size>100 100</size>
            </plane>
          </geometry>
          <material>
            <script>
              <uri>file://media/materials/scripts/gazebo.material</uri>
              <name>Gazebo/Grey</name>
            </script>
          </material>
        </visual>
        <self_collide>0</self_collide>
        <enable_wind>0</enable_wind>
        <gravity>1</gravity>
      </link>
    </model>
    <gravity>0 0 -9.8</gravity>
    <magnetic_field>6e-06 2.3e-05 -4.2e-05</magnetic_field>
    <atmosphere type='adiabatic'/>
    <scene>
      <ambient>0.4 0.4 0.4 1</ambient>
      <background>0.7 0.7 0.7 1</background>
      <shadows>1</shadows>
    </scene>
    <wind/>
    <spherical_coordinates>
      <surface_model>EARTH_WGS84</surface_model>
      <latitude_deg>0</latitude_deg>
      <longitude_deg>0</longitude_deg>
      <elevation>0</elevation>
      <heading_deg>0</heading_deg>
    </spherical_coordinates>
    <model name='velma'>
      <link name='torso_base'>
        <pose frame=''>0 0 0 0 -0 0</pose>
        <inertial>
          <pose frame=''>0 -0.06 0.13 0 -0 0</pose>
          <mass>30</mass>
          <inertia>
            <ixx>0.9</ixx>
            <ixy>0</ixy>
            <ixz>0</ixz>
            <iyy>0.9</iyy>
            <iyz>0</iyz>
            <izz>1.35</izz>
          </inertia>
        </inertial>
        <visual name='torso_base_visual'>
          <pose frame=''>0 0 0.1 0 -0 0</pose>
          <geometry>
            <mesh>
              <scale>1 1 1</scale>
              <uri>/opt/ws_velma_os/share/velma_description/meshes/torso_base.STL</uri>
            </mesh>
          </geometry>
          <material>
            <script>
              <uri>__default__</uri>
              <name>__default__</name>
            </script>
          </material>
        </visual>
        <gravity>1</gravity>
        <velocity_decay/>
        <self_collide>1</self_collide>
        <enable_wind>0</enable_wind>
      </link>
      <joint name='torso_base_joint' type='fixed'>
        <child>torso_base</child>
        <parent>world</parent>
      </joint>
      <link name='torso_link0'>
        <pose frame=''>0 0 0.1 0 -0 0</pose>
        <inertial>
          <pose frame=''>0.000239 -0.052331 0.26913 0 -0 0</pose>
          <mass>34.4</mass>
          <inertia>
            <ixx>7.75895</ixx>
            <ixy>-0.000425999</ixy>
            <ixz>-0.00917111</ixz>
            <iyy>7.73661</iyy>
            <iyz>-0.250246</iyz>
            <izz>1.38178</izz>
          </inertia>
        </inertial>
        <collision name='torso_link0_collision'>
          <pose frame=''>0 0 0.52 0 -0 0</pose>
          <geometry>
            <mesh>
              <scale>1 1 1</scale>
              <uri>/opt/ws_velma_os/share/velma_description/meshes/collision/torso0_collision.stl</uri>
            </mesh>
          </geometry>
          <surface>
            <contact>
              <ode/>
            </contact>
            <friction>
              <ode/>
            </friction>
          </surface>
          <max_contacts>10</max_contacts>
        </collision>
        <collision name='torso_link0_fixed_joint_lump__head_base_collision_1'>
          <pose frame=''>0.020988 -0.000414 1.3117 0.000403 -0.006272 -0.048944</pose>
          <geometry>
            <mesh>
              <scale>1 1 1</scale>
              <uri>/opt/ws_velma_os/share/velma_description/meshes/collision/head_base_collision.STL</uri>
            </mesh>
          </geometry>
          <max_contacts>10</max_contacts>
          <surface>
            <contact/>
            <friction>
              <ode/>
            </friction>
          </surface>
        </collision>
        <collision name='torso_link0_fixed_joint_lump__head_pan_motor_collision_2'>
          <pose frame=''>0.020637 -0.00042 1.3675 0.000403 -0.006272 -0.048944</pose>
          <geometry>
            <box>
              <size>0.14 0.09 0.06</size>
            </box>
          </geometry>
          <max_contacts>10</max_contacts>
          <surface>
            <contact/>
            <friction>
              <ode/>
            </friction>
          </surface>
        </collision>
        <collision name='torso_link0_fixed_joint_lump__calib_left_arm_base_link_collision_3'>
          <pose frame=''>0 0.04782 1.20085 0 -1.0472 -1.5708</pose>
          <geometry>
            <mesh>
              <scale>1 1 1</scale>
              <uri>/opt/ws_velma_os/share/lwr_defs/meshes/lwr/convex/arm_base_convex.stl</uri>
            </mesh>
          </geometry>
          <surface>
            <contact>
              <ode/>
            </contact>
            <friction>
              <ode/>
            </friction>
          </surface>
          <max_contacts>10</max_contacts>
        </collision>
        <collision name='torso_link0_fixed_joint_lump__calib_right_arm_base_link_collision_4'>
          <pose frame=''>-0 -0.04782 1.20085 -0 1.0472 -1.5708</pose>
          <geometry>
            <mesh>
              <scale>1 1 1</scale>
              <uri>/opt/ws_velma_os/share/lwr_defs/meshes/lwr/convex/arm_base_convex.stl</uri>
            </mesh>
          </geometry>
          <surface>
            <contact>
              <ode/>
            </contact>
            <friction>
              <ode/>
            </friction>
          </surface>
          <max_contacts>10</max_contacts>
        </collision>
        <visual name='torso_link0_visual'>
          <pose frame=''>0 0 0.52 0 -0 0</pose>
          <geometry>
            <mesh>
              <scale>1 1 1</scale>
              <uri>/opt/ws_velma_os/share/velma_description/meshes/collision/torso0_collision.stl</uri>
            </mesh>
          </geometry>
          <material>
            <script>
              <uri>__default__</uri>
              <name>__default__</name>
            </script>
          </material>
        </visual>
        <visual name='torso_link0_fixed_joint_lump__head_base_visual_1'>
          <pose frame=''>0.020988 -0.000414 1.3117 0.000403 -0.006272 -0.048944</pose>
          <geometry>
            <mesh>
              <scale>1 1 1</scale>
              <uri>/opt/ws_velma_os/share/velma_description/meshes/head_base_simplified.STL</uri>
            </mesh>
          </geometry>
        </visual>
        <visual name='torso_link0_fixed_joint_lump__head_pan_motor_visual_2'>
          <pose frame=''>0.020831 -0.000417 1.3367 0.000403 -0.006272 -0.048944</pose>
          <geometry>
            <mesh>
              <scale>1 1 1</scale>
              <uri>/opt/ws_velma_os/share/velma_description/meshes/head_pan_simplified.STL</uri>
            </mesh>
          </geometry>
        </visual>
        <visual name='torso_link0_fixed_joint_lump__calib_left_arm_base_link_visual_3'>
          <pose frame=''>0 0.000189 1.17335 0 1.0472 1.5708</pose>
          <geometry>
            <mesh>
              <scale>1 1 1</scale>
              <uri>/opt/ws_velma_os/share/lwr_defs/meshes/lwr/base_simplified.STL</uri>
            </mesh>
          </geometry>
          <material>
            <script>
              <uri>__default__</uri>
              <name>__default__</name>
            </script>
          </material>
        </visual>
        <visual name='torso_link0_fixed_joint_lump__calib_right_arm_base_link_visual_4'>
          <pose frame=''>0 -0.000189 1.17335 -0 -1.0472 1.5708</pose>
          <geometry>
            <mesh>
              <scale>1 1 1</scale>
              <uri>/opt/ws_velma_os/share/lwr_defs/meshes/lwr/base_simplified.STL</uri>
            </mesh>
          </geometry>
          <material>
            <script>
              <uri>__default__</uri>
              <name>__default__</name>
            </script>
          </material>
        </visual>
        <velocity_decay/>
        <velocity_decay/>
        <gravity>1</gravity>
        <velocity_decay/>
        <self_collide>1</self_collide>
        <enable_wind>0</enable_wind>
      </link>
      <joint name='torso_0_joint' type='revolute'>
        <child>torso_link0</child>
        <parent>torso_base</parent>
        <axis>
          <xyz>0 0 1</xyz>
          <limit>
            <lower>-1.57</lower>
            <upper>1.57</upper>
            <effort>100</effort>
            <velocity>100</velocity>
          </limit>
          <dynamics>
            <damping>10</damping>
            <friction>0</friction>
            <spring_reference>0</spring_reference>
            <spring_stiffness>0</spring_stiffness>
          </dynamics>
          <use_parent_model_frame>1</use_parent_model_frame>
        </axis>
      </joint>
      <link name='head_pan_link'>
        <pose frame=''>0.020441 -0.000423 1.4987 0.000403 -0.006272 -0.048944</pose>
        <inertial>
          <pose frame=''>0 0 0.0625 0 -0 0</pose>
          <mass>0.2</mass>
          <inertia>
            <ixx>0.000520833</ixx>
            <ixy>0</ixy>
            <ixz>0</ixz>
            <iyy>0.000520833</iyy>
            <iyz>0</iyz>
            <izz>0.000520833</izz>
          </inertia>
        </inertial>
        <collision name='head_pan_link_collision'>
          <pose frame=''>0 -0.00921 0.04463 0 -0 0</pose>
          <geometry>
            <box>
              <size>0.08 0.08 0.08</size>
            </box>
          </geometry>
          <surface>
            <contact>
              <ode/>
            </contact>
            <friction>
              <ode/>
            </friction>
          </surface>
          <max_contacts>10</max_contacts>
        </collision>
        <visual name='head_pan_link_visual'>
          <pose frame=''>0 0 0 0 -0 0</pose>
          <geometry>
            <mesh>
              <scale>1 1 1</scale>
              <uri>/opt/ws_velma_os/share/velma_description/meshes/head_tilt_simplified.STL</uri>
            </mesh>
          </geometry>
          <material>
            <script>
              <uri>__default__</uri>
              <name>__default__</name>
            </script>
          </material>
        </visual>
        <gravity>1</gravity>
        <velocity_decay/>
        <self_collide>1</self_collide>
        <enable_wind>0</enable_wind>
      </link>
      <joint name='head_pan_joint' type='revolute'>
        <child>head_pan_link</child>
        <parent>torso_link0</parent>
        <axis>
          <xyz>-0.006285 -9.6e-05 0.99998</xyz>
          <limit>
            <lower>-1.57</lower>
            <upper>1.57</upper>
            <effort>100</effort>
            <velocity>1.57</velocity>
          </limit>
          <dynamics>
            <damping>0.1</damping>
            <friction>0</friction>
            <spring_reference>0</spring_reference>
            <spring_stiffness>0</spring_stiffness>
          </dynamics>
          <use_parent_model_frame>1</use_parent_model_frame>
        </axis>
      </joint>
      <link name='head_tilt_link'>
        <pose frame=''>0.02014 -0.000427 1.5467 1.5704 -0.006272 -0.048944</pose>
        <inertial>
          <pose frame=''>0 0 0.0625 0 -0 0</pose>
          <mass>0.2</mass>
          <inertia>
            <ixx>0.000520833</ixx>
            <ixy>0</ixy>
            <ixz>0</ixz>
            <iyy>0.000520833</iyy>
            <iyz>0</iyz>
            <izz>0.000520833</izz>
          </inertia>
        </inertial>
        <collision name='head_tilt_link_collision'>
          <pose frame=''>0 0 0.04219 0 -0 0</pose>
          <geometry>
            <mesh>
              <scale>1 1 1</scale>
              <uri>/opt/ws_velma_os/share/velma_description/meshes/collision/head_top_collision.STL</uri>
            </mesh>
          </geometry>
          <surface>
            <contact>
              <ode/>
            </contact>
            <friction>
              <ode/>
            </friction>
          </surface>
          <max_contacts>10</max_contacts>
        </collision>
        <visual name='head_tilt_link_visual'>
          <pose frame=''>0 0 0.04219 0 -0 0</pose>
          <geometry>
            <mesh>
              <scale>1 1 1</scale>
              <uri>/opt/ws_velma_os/share/velma_description/meshes/head_top_simplified.STL</uri>
            </mesh>
          </geometry>
          <material>
            <script>
              <uri>__default__</uri>
              <name>__default__</name>
            </script>
          </material>
        </visual>
        <visual name='head_tilt_link_visual_1'>
          <pose frame=''>0 0 0.04219 0 -0 0</pose>
          <geometry>
            <mesh>
              <scale>1 1 1</scale>
              <uri>/opt/ws_velma_os/share/velma_description/meshes/collision/head_top_collision.STL</uri>
            </mesh>
          </geometry>
          <material>
            <script>
              <uri>__default__</uri>
              <name>__default__</name>
            </script>
          </material>
        </visual>
        <velocity_decay/>
        <self_collide>1</self_collide>
        <gravity>1</gravity>
        <velocity_decay/>
        <sensor name='openni_camera_camera' type='depth'>
          <always_on>0</always_on>
          <update_rate>15</update_rate>
          <visualize>0</visualize>
          <camera name='__default__'>
            <horizontal_fov>1.047</horizontal_fov>
            <image>
              <width>800</width>
              <height>600</height>
              <format>B8G8R8</format>
            </image>
            <depth_camera>
              <output>depths</output>
            </depth_camera>
            <clip>
              <near>0.1</near>
              <far>10</far>
            </clip>
          </camera>
          <plugin name='kinect_controller' filename='libgazebo_ros_openni_kinect.so'>
            <baseline>0.2</baseline>
            <cameraName>head_kinect_ir</cameraName>
            <imageTopicName>/head_kinect/rgb/image_raw</imageTopicName>
            <cameraInfoTopicName>/head_kinect/rgb/camera_info</cameraInfoTopicName>
            <depthImageTopicName>/head_kinect/depth/image_raw</depthImageTopicName>
            <depthImageCameraInfoTopicName>/head_kinect/depth/camera_info</depthImageCameraInfoTopicName>
            <pointCloudTopicName>/head_kinect/depth/points</pointCloudTopicName>
            <frameName>head_kinect_rgb_optical_frame</frameName>
            <pointCloudCutoff>0.5</pointCloudCutoff>
            <pointCloudCutoffMax>3.0</pointCloudCutoffMax>
            <distortionK1>0.00000001</distortionK1>
            <distortionK2>0.00000001</distortionK2>
            <distortionK3>0.00000001</distortionK3>
            <distortionT1>0.00000001</distortionT1>
            <distortionT2>0.00000001</distortionT2>
            <CxPrime>0</CxPrime>
            <Cx>0</Cx>
            <Cy>0</Cy>
            <focalLength>0</focalLength>
            <hackBaseline>0</hackBaseline>
            <robotNamespace>/</robotNamespace>
          </plugin>
          <pose frame=''>0.062644 0.19458 0.017223 -1.5527 0.015593 -0.094166</pose>
        </sensor>
        <enable_wind>0</enable_wind>
      </link>
      <joint name='head_tilt_joint' type='revolute'>
        <child>head_tilt_link</child>
        <parent>head_pan_link</parent>
        <axis>
          <xyz>0.048927 0.998802 -0.000393</xyz>
          <limit>
            <lower>-1.57</lower>
            <upper>1.57</upper>
            <effort>100</effort>
            <velocity>100</velocity>
          </limit>
          <dynamics>
            <damping>0.1</damping>
            <friction>0</friction>
            <spring_reference>0</spring_reference>
            <spring_stiffness>0</spring_stiffness>
          </dynamics>
          <use_parent_model_frame>1</use_parent_model_frame>
        </axis>
      </joint>
      <link name='left_arm_1_link'>
        <pose frame=''>0 0.095452 1.32835 0 1.0472 1.5708</pose>
        <inertial>
          <pose frame=''>0 -0.06 0.13 0 -0 0</pose>
          <mass>2</mass>
          <inertia>
            <ixx>0.0136667</ixx>
            <ixy>0</ixy>
            <ixz>0</ixz>
            <iyy>0.003</iyy>
            <iyz>0</iyz>
            <izz>0.0118667</izz>
          </inertia>
        </inertial>
        <collision name='left_arm_1_link_collision'>
          <pose frame=''>0 0 0 0 -0 0</pose>
          <geometry>
            <mesh>
              <scale>1 1 1</scale>
              <uri>/opt/ws_velma_os/share/lwr_defs/meshes/lwr/convex/arm_segment_a_convex.stl</uri>
            </mesh>
          </geometry>
          <surface>
            <contact>
              <ode/>
            </contact>
            <friction>
              <ode/>
            </friction>
          </surface>
          <max_contacts>10</max_contacts>
        </collision>
        <visual name='left_arm_1_link_visual'>
          <pose frame=''>0 0 -0.008 0 -0 0</pose>
          <geometry>
            <mesh>
              <scale>1 1 1</scale>
              <uri>/opt/ws_velma_os/share/lwr_defs/meshes/lwr/link_1_simplified.STL</uri>
            </mesh>
          </geometry>
          <material>
            <script>
              <uri>__default__</uri>
              <name>__default__</name>
            </script>
          </material>
        </visual>
        <gravity>1</gravity>
        <velocity_decay/>
        <self_collide>1</self_collide>
        <enable_wind>0</enable_wind>
      </link>
      <joint name='left_arm_0_joint' type='revolute'>
        <child>left_arm_1_link</child>
        <parent>torso_link0</parent>
        <axis>
          <xyz>0 0.866025 0.5</xyz>
          <limit>
            <lower>-2.96706</lower>
            <upper>2.96706</upper>
            <effort>204</effort>
            <velocity>1.91986</velocity>
          </limit>
          <dynamics>
            <damping>1</damping>
            <friction>0</friction>
            <spring_reference>0</spring_reference>
            <spring_stiffness>0</spring_stiffness>
          </dynamics>
          <use_parent_model_frame>1</use_parent_model_frame>
        </axis>
      </joint>
      <link name='left_arm_2_link'>
        <pose frame=''>0 0.26909 1.4286 0 1.0472 1.5708</pose>
        <inertial>
          <pose frame=''>0 0.06 0.07 0 -0 0</pose>
          <mass>2</mass>
          <inertia>
            <ixx>0.0136667</ixx>
            <ixy>0</ixy>
            <ixz>0</ixz>
            <iyy>0.003</iyy>
            <iyz>0</iyz>
            <izz>0.0118667</izz>
          </inertia>
        </inertial>
        <collision name='left_arm_2_link_collision'>
          <pose frame=''>0 0 0.2 -3.14159 -0 0</pose>
          <geometry>
            <mesh>
              <scale>1 1 1</scale>
              <uri>/opt/ws_velma_os/share/lwr_defs/meshes/lwr/convex/arm_segment_b_convex.stl</uri>
            </mesh>
          </geometry>
          <surface>
            <contact>
              <ode/>
            </contact>
            <friction>
              <ode/>
            </friction>
          </surface>
          <max_contacts>10</max_contacts>
        </collision>
        <visual name='left_arm_2_link_visual'>
          <pose frame=''>0 0 0 0 -0 0</pose>
          <geometry>
            <mesh>
              <scale>1 1 1</scale>
              <uri>/opt/ws_velma_os/share/lwr_defs/meshes/lwr/link_2_simplified.STL</uri>
            </mesh>
          </geometry>
          <material>
            <script>
              <uri>__default__</uri>
              <name>__default__</name>
            </script>
          </material>
        </visual>
        <gravity>1</gravity>
        <velocity_decay/>
        <self_collide>1</self_collide>
        <enable_wind>0</enable_wind>
      </link>
      <joint name='left_arm_1_joint' type='revolute'>
        <child>left_arm_2_link</child>
        <parent>left_arm_1_link</parent>
        <axis>
          <xyz>-1 0 0</xyz>
          <limit>
            <lower>-2.0944</lower>
            <upper>2.0944</upper>
            <effort>306</effort>
            <velocity>1.91986</velocity>
          </limit>
          <dynamics>
            <damping>1</damping>
            <friction>0</friction>
            <spring_reference>0</spring_reference>
            <spring_stiffness>0</spring_stiffness>
          </dynamics>
          <use_parent_model_frame>1</use_parent_model_frame>
        </axis>
      </joint>
      <link name='left_arm_3_link'>
        <pose frame=''>0 0.442295 1.5286 0 1.0472 1.5708</pose>
        <inertial>
          <pose frame=''>0 0.06 0.13 0 -0 0</pose>
          <mass>2</mass>
          <inertia>
            <ixx>0.0136667</ixx>
            <ixy>0</ixy>
            <ixz>0</ixz>
            <iyy>0.003</iyy>
            <iyz>0</iyz>
            <izz>0.0118667</izz>
          </inertia>
        </inertial>
        <collision name='left_arm_3_link_collision'>
          <pose frame=''>0 0 0 0 -0 -3.14159</pose>
          <geometry>
            <mesh>
              <scale>1 1 1</scale>
              <uri>/opt/ws_velma_os/share/lwr_defs/meshes/lwr/convex/arm_segment_a_convex.stl</uri>
            </mesh>
          </geometry>
          <surface>
            <contact>
              <ode/>
            </contact>
            <friction>
              <ode/>
            </friction>
          </surface>
          <max_contacts>10</max_contacts>
        </collision>
        <visual name='left_arm_3_link_visual'>
          <pose frame=''>0 0 -0.008 0 -0 0</pose>
          <geometry>
            <mesh>
              <scale>1 1 1</scale>
              <uri>/opt/ws_velma_os/share/lwr_defs/meshes/lwr/link_3_simplified.STL</uri>
            </mesh>
          </geometry>
          <material>
            <script>
              <uri>__default__</uri>
              <name>__default__</name>
            </script>
          </material>
        </visual>
        <gravity>1</gravity>
        <velocity_decay/>
        <self_collide>1</self_collide>
        <enable_wind>0</enable_wind>
      </link>
      <joint name='left_arm_2_joint' type='revolute'>
        <child>left_arm_3_link</child>
        <parent>left_arm_2_link</parent>
        <axis>
          <xyz>0 0.866025 0.5</xyz>
          <limit>
            <lower>-2.96706</lower>
            <upper>2.96706</upper>
            <effort>204</effort>
            <velocity>2.26893</velocity>
          </limit>
          <dynamics>
            <damping>1</damping>
            <friction>0</friction>
            <spring_reference>0</spring_reference>
            <spring_stiffness>0</spring_stiffness>
          </dynamics>
          <use_parent_model_frame>1</use_parent_model_frame>
        </axis>
      </joint>
      <link name='left_arm_4_link'>
        <pose frame=''>0 0.6155 1.6286 0 1.0472 1.5708</pose>
        <inertial>
          <pose frame=''>0 -0.06 0.07 0 -0 0</pose>
          <mass>2</mass>
          <inertia>
            <ixx>0.0136667</ixx>
            <ixy>0</ixy>
            <ixz>0</ixz>
            <iyy>0.003</iyy>
            <iyz>0</iyz>
            <izz>0.0118667</izz>
          </inertia>
        </inertial>
        <collision name='left_arm_4_link_collision'>
          <pose frame=''>0 0 0.2 3.14159 -0 3.14159</pose>
          <geometry>
            <mesh>
              <scale>1 1 1</scale>
              <uri>/opt/ws_velma_os/share/lwr_defs/meshes/lwr/convex/arm_segment_b_convex.stl</uri>
            </mesh>
          </geometry>
          <surface>
            <contact>
              <ode/>
            </contact>
            <friction>
              <ode/>
            </friction>
          </surface>
          <max_contacts>10</max_contacts>
        </collision>
        <visual name='left_arm_4_link_visual'>
          <pose frame=''>0 0 0 0 -0 0</pose>
          <geometry>
            <mesh>
              <scale>1 1 1</scale>
              <uri>/opt/ws_velma_os/share/lwr_defs/meshes/lwr/link_4_simplified.STL</uri>
            </mesh>
          </geometry>
          <material>
            <script>
              <uri>__default__</uri>
              <name>__default__</name>
            </script>
          </material>
        </visual>
        <gravity>1</gravity>
        <velocity_decay/>
        <self_collide>1</self_collide>
        <enable_wind>0</enable_wind>
      </link>
      <joint name='left_arm_3_joint' type='revolute'>
        <child>left_arm_4_link</child>
        <parent>left_arm_3_link</parent>
        <axis>
          <xyz>1 -0 -0</xyz>
          <limit>
            <lower>-2.0944</lower>
            <upper>2.0944</upper>
            <effort>306</effort>
            <velocity>2.26893</velocity>
          </limit>
          <dynamics>
            <damping>1</damping>
            <friction>0</friction>
            <spring_reference>0</spring_reference>
            <spring_stiffness>0</spring_stiffness>
          </dynamics>
          <use_parent_model_frame>1</use_parent_model_frame>
        </axis>
      </joint>
      <link name='left_arm_5_link'>
        <pose frame=''>0 0.788705 1.7286 0 1.0472 1.5708</pose>
        <inertial>
          <pose frame=''>0 0 0.124 0 -0 0</pose>
          <mass>2</mass>
          <inertia>
            <ixx>0.0126507</ixx>
            <ixy>0</ixy>
            <ixz>0</ixz>
            <iyy>0.003</iyy>
            <iyz>0</iyz>
            <izz>0.0108507</izz>
          </inertia>
        </inertial>
        <collision name='left_arm_5_link_collision'>
          <pose frame=''>0 0 0 0 -0 0</pose>
          <geometry>
            <mesh>
              <scale>1 1 1</scale>
              <uri>/opt/ws_velma_os/share/lwr_defs/meshes/lwr/convex/arm_segment_last_convex.stl</uri>
            </mesh>
          </geometry>
          <surface>
            <contact>
              <ode/>
            </contact>
            <friction>
              <ode/>
            </friction>
          </surface>
          <max_contacts>10</max_contacts>
        </collision>
        <visual name='left_arm_5_link_visual'>
          <pose frame=''>0 0 -0.008 0 -0 0</pose>
          <geometry>
            <mesh>
              <scale>1 1 1</scale>
              <uri>/opt/ws_velma_os/share/lwr_defs/meshes/lwr/link_5_simplified.STL</uri>
            </mesh>
          </geometry>
          <material>
            <script>
              <uri>__default__</uri>
              <name>__default__</name>
            </script>
          </material>
        </visual>
        <gravity>1</gravity>
        <velocity_decay/>
        <self_collide>1</self_collide>
        <enable_wind>0</enable_wind>
      </link>
      <joint name='left_arm_4_joint' type='revolute'>
        <child>left_arm_5_link</child>
        <parent>left_arm_4_link</parent>
        <axis>
          <xyz>0 0.866025 0.5</xyz>
          <limit>
            <lower>-2.96706</lower>
            <upper>2.96706</upper>
            <effort>204</effort>
            <velocity>2.26893</velocity>
          </limit>
          <dynamics>
            <damping>1</damping>
            <friction>0</friction>
            <spring_reference>0</spring_reference>
            <spring_stiffness>0</spring_stiffness>
          </dynamics>
          <use_parent_model_frame>1</use_parent_model_frame>
        </axis>
      </joint>
      <link name='left_arm_6_link'>
        <pose frame=''>0 0.95325 1.8236 0 1.0472 1.5708</pose>
        <inertial>
          <pose frame=''>0 0 0.0625 0 -0 0</pose>
          <mass>0.2</mass>
          <inertia>
            <ixx>0.000520833</ixx>
            <ixy>0</ixy>
            <ixz>0</ixz>
            <iyy>0.000520833</iyy>
            <iyz>0</iyz>
            <izz>0.000520833</izz>
          </inertia>
        </inertial>
        <collision name='left_arm_6_link_collision'>
          <pose frame=''>0 0 0 0 -0 0</pose>
          <geometry>
            <mesh>
              <scale>1 1 1</scale>
              <uri>/opt/ws_velma_os/share/lwr_defs/meshes/lwr/convex/arm_wrist_convex.stl</uri>
            </mesh>
          </geometry>
          <surface>
            <contact>
              <ode/>
            </contact>
            <friction>
              <ode/>
            </friction>
          </surface>
          <max_contacts>10</max_contacts>
        </collision>
        <visual name='left_arm_6_link_visual'>
          <pose frame=''>0 0 0 0 -0 0</pose>
          <geometry>
            <mesh>
              <scale>1 1 1</scale>
              <uri>/opt/ws_velma_os/share/lwr_defs/meshes/lwr/link_6_simplified.STL</uri>
            </mesh>
          </geometry>
          <material>
            <script>
              <uri>__default__</uri>
              <name>__default__</name>
            </script>
          </material>
        </visual>
        <gravity>1</gravity>
        <velocity_decay/>
        <self_collide>1</self_collide>
        <enable_wind>0</enable_wind>
      </link>
      <joint name='left_arm_5_joint' type='revolute'>
        <child>left_arm_6_link</child>
        <parent>left_arm_5_link</parent>
        <axis>
          <xyz>-1 0 0</xyz>
          <limit>
            <lower>-2.0944</lower>
            <upper>2.0944</upper>
            <effort>306</effort>
            <velocity>3.14159</velocity>
          </limit>
          <dynamics>
            <damping>1</damping>
            <friction>0</friction>
            <spring_reference>0</spring_reference>
            <spring_stiffness>0</spring_stiffness>
          </dynamics>
          <use_parent_model_frame>1</use_parent_model_frame>
        </axis>
      </joint>
      <link name='left_arm_7_link'>
        <pose frame=''>0 1.0208 1.8626 0 1.0472 1.5708</pose>
        <inertial>
          <pose frame=''>-0.05398 -3.1e-05 -0.031139 0 -0 0</pose>
          <mass>0.291212</mass>
          <inertia>
            <ixx>0.00107689</ixx>
            <ixy>-3.40075e-09</ixy>
            <ixz>-0.00056961</ixz>
            <iyy>0.00170618</iyy>
            <iyz>-1.96175e-09</iyz>
            <izz>0.0012739</izz>
          </inertia>
        </inertial>
        <collision name='left_arm_7_link_fixed_joint_lump__left_gripper_mount_link_collision'>
          <pose frame=''>0 0 0 0 -0 -3.14159</pose>
          <geometry>
            <mesh>
              <scale>1 1 1</scale>
              <uri>/opt/ws_velma_os/share/velma_description/meshes/collision/gripper_mount_collision2.STL</uri>
            </mesh>
          </geometry>
          <surface>
            <contact>
              <ode/>
            </contact>
            <friction>
              <ode/>
            </friction>
          </surface>
          <max_contacts>10</max_contacts>
        </collision>
        <visual name='left_arm_7_link_visual'>
          <pose frame=''>0 0 0 0 -0 0</pose>
          <geometry>
            <mesh>
              <scale>1 1 1</scale>
              <uri>/opt/ws_velma_os/share/lwr_defs/meshes/lwr/link_7_simplified.STL</uri>
            </mesh>
          </geometry>
          <material>
            <script>
              <uri>__default__</uri>
              <name>__default__</name>
            </script>
          </material>
        </visual>
        <visual name='left_arm_7_link_fixed_joint_lump__left_gripper_mount_link_visual_1'>
          <pose frame=''>0 0 0 0 -0 -3.14159</pose>
          <geometry>
            <mesh>
              <scale>1 1 1</scale>
              <uri>/opt/ws_velma_os/share/velma_description/meshes/gripper_mount_simplified.stl</uri>
            </mesh>
          </geometry>
          <material>
            <script>
              <uri>__default__</uri>
              <name>__default__</name>
            </script>
          </material>
        </visual>
        <velocity_decay/>
        <gravity>1</gravity>
        <velocity_decay/>
        <self_collide>1</self_collide>
        <enable_wind>0</enable_wind>
      </link>
      <joint name='left_arm_6_joint' type='revolute'>
        <child>left_arm_7_link</child>
        <parent>left_arm_6_link</parent>
        <axis>
          <xyz>0 0.866025 0.5</xyz>
          <limit>
            <lower>-2.96706</lower>
            <upper>2.96706</upper>
            <effort>204</effort>
            <velocity>3.14159</velocity>
          </limit>
          <dynamics>
            <damping>1</damping>
            <friction>0</friction>
            <spring_reference>0</spring_reference>
            <spring_stiffness>0</spring_stiffness>
          </dynamics>
          <use_parent_model_frame>1</use_parent_model_frame>
        </axis>
        <physics>
          <provide_feedback>1</provide_feedback>
          <ode>
            <provide_feedback>1</provide_feedback>
            <limit>
              <cfm>0</cfm>
              <erp>0.2</erp>
            </limit>
          </ode>
        </physics>
      </joint>
      <link name='left_FtSensorLink'>
        <pose frame=''>0 0.89575 1.92319 -0 0.523599 -1.5708</pose>
        <inertial>
          <pose frame=''>-0.000354 0.004974 0.048497 0 -0 0</pose>
          <mass>0.635529</mass>
          <inertia>
            <ixx>0.00103101</ixx>
            <ixy>7.75353e-06</ixy>
            <ixz>1.23344e-05</ixz>
            <iyy>0.000819367</iyy>
            <iyz>0.000143686</iyz>
            <izz>0.000693138</izz>
          </inertia>
        </inertial>
        <collision name='left_FtSensorLink_fixed_joint_lump__left_HandPalmLink_collision'>
          <pose frame=''>0 0 0 0 -0 -3.14159</pose>
          <geometry>
            <mesh>
              <scale>1 1 1</scale>
              <uri>/opt/ws_velma_os/share/barrett_hand_defs/meshes/palm.stl</uri>
            </mesh>
          </geometry>
          <surface>
            <contact>
              <ode/>
            </contact>
            <friction>
              <ode/>
            </friction>
          </surface>
          <max_contacts>10</max_contacts>
        </collision>
        <visual name='left_FtSensorLink_fixed_joint_lump__left_HandPalmLink_visual'>
          <pose frame=''>0 0 0 0 -0 -3.14159</pose>
          <geometry>
            <mesh>
              <scale>1 1 1</scale>
              <uri>/opt/ws_velma_os/share/barrett_hand_defs/meshes/palm.stl</uri>
            </mesh>
          </geometry>
          <material>
            <script>
              <uri>__default__</uri>
              <name>__default__</name>
            </script>
          </material>
        </visual>
        <velocity_decay/>
        <velocity_decay/>
        <gravity>1</gravity>
        <velocity_decay/>
        <self_collide>1</self_collide>
        <enable_wind>0</enable_wind>
      </link>
      <joint name='leftFtSensorJoint' type='revolute'>
        <child>left_FtSensorLink</child>
        <parent>left_arm_7_link</parent>
        <axis>
          <xyz>-0 -0.5 0.866025</xyz>
          <limit>
            <lower>0</lower>
            <upper>0</upper>
            <effort>10</effort>
            <velocity>3.27</velocity>
          </limit>
          <dynamics>
            <damping>0.05</damping>
            <friction>0</friction>
            <spring_reference>0</spring_reference>
            <spring_stiffness>0</spring_stiffness>
          </dynamics>
          <use_parent_model_frame>1</use_parent_model_frame>
        </axis>
        <physics>
          <provide_feedback>1</provide_feedback>
          <ode>
            <provide_feedback>1</provide_feedback>
            <limit>
              <cfm>0</cfm>
              <erp>0.2</erp>
            </limit>
          </ode>
        </physics>
      </joint>
      <link name='left_HandFingerOneKnuckleOneLink'>
        <pose frame=''>0 0.887976 1.9866 -0.523599 0 3.14159</pose>
        <inertial>
          <pose frame=''>0.032017 -0.000865 0.008901 0 -0 0</pose>
          <mass>0.162527</mass>
          <inertia>
            <ixx>2.567e-05</ixx>
            <ixy>-1.46e-06</ixy>
            <ixz>1.128e-05</ixz>
            <iyy>8.818e-05</iyy>
            <iyz>-9.4e-07</iyz>
            <izz>7.827e-05</izz>
          </inertia>
        </inertial>
        <collision name='left_HandFingerOneKnuckleOneLink_collision'>
          <pose frame=''>0 0 -0.0045 1.5708 0 -1.5708</pose>
          <geometry>
            <mesh>
              <scale>1 1 1</scale>
              <uri>/opt/ws_velma_os/share/barrett_hand_defs/meshes/firstFingerLink.stl</uri>
            </mesh>
          </geometry>
          <surface>
            <contact>
              <ode/>
            </contact>
            <friction>
              <ode/>
            </friction>
          </surface>
          <max_contacts>10</max_contacts>
        </collision>
        <visual name='left_HandFingerOneKnuckleOneLink_visual'>
          <pose frame=''>0 0 -0.0045 1.5708 0 -1.5708</pose>
          <geometry>
            <mesh>
              <scale>1 1 1</scale>
              <uri>/opt/ws_velma_os/share/barrett_hand_defs/meshes/firstFingerLink.stl</uri>
            </mesh>
          </geometry>
          <material>
            <script>
              <uri>__default__</uri>
              <name>__default__</name>
            </script>
          </material>
        </visual>
        <gravity>1</gravity>
        <velocity_decay/>
        <self_collide>1</self_collide>
        <enable_wind>0</enable_wind>
      </link>
      <joint name='left_HandFingerOneKnuckleOneJoint' type='revolute'>
        <child>left_HandFingerOneKnuckleOneLink</child>
        <parent>left_FtSensorLink</parent>
        <axis>
          <xyz>0 0.5 -0.866025</xyz>
          <limit>
            <lower>0</lower>
            <upper>3.14159</upper>
            <effort>1</effort>
            <velocity>3.27</velocity>
          </limit>
          <dynamics>
            <damping>0.1</damping>
            <friction>0</friction>
            <spring_reference>0</spring_reference>
            <spring_stiffness>0</spring_stiffness>
          </dynamics>
          <use_parent_model_frame>1</use_parent_model_frame>
        </axis>
        <physics>
          <provide_feedback>1</provide_feedback>
          <ode>
            <provide_feedback>1</provide_feedback>
            <limit>
              <cfm>0</cfm>
              <erp>0.2</erp>
            </limit>
          </ode>
        </physics>
      </joint>
      <link name='left_HandFingerOneKnuckleTwoLink'>
        <pose frame=''>-0.05 0.879674 2.00098 -2.0944 -0 3.14159</pose>
        <inertial>
          <pose frame=''>0.03172 0.00107 -0.000586 0 -0 0</pose>
          <mass>0.057957</mass>
          <inertia>
            <ixx>4.61e-06</ixx>
            <ixy>3e-08</ixy>
            <ixz>1.64e-06</ixz>
            <iyy>3.59e-05</iyy>
            <iyz>4e-08</iyz>
            <izz>3.682e-05</izz>
          </inertia>
        </inertial>
        <collision name='left_HandFingerOneKnuckleTwoLink_collision'>
          <pose frame=''>0.03 0 0 0 -0 0</pose>
          <geometry>
            <box>
              <size>0.07 0.02 0.02</size>
            </box>
          </geometry>
          <surface>
            <contact>
              <ode/>
            </contact>
            <friction>
              <ode/>
            </friction>
          </surface>
          <max_contacts>10</max_contacts>
        </collision>
        <visual name='left_HandFingerOneKnuckleTwoLink_visual'>
          <pose frame=''>0 0 0 3.14159 1.57079 3e-06</pose>
          <geometry>
            <mesh>
              <scale>1 1 1</scale>
              <uri>/opt/ws_velma_os/share/barrett_hand_defs/meshes/secondFingerLink.stl</uri>
            </mesh>
          </geometry>
          <material>
            <script>
              <uri>__default__</uri>
              <name>__default__</name>
            </script>
          </material>
        </visual>
        <gravity>1</gravity>
        <velocity_decay/>
        <self_collide>1</self_collide>
        <enable_wind>0</enable_wind>
      </link>
      <joint name='left_HandFingerOneKnuckleTwoJoint' type='revolute'>
        <child>left_HandFingerOneKnuckleTwoLink</child>
        <parent>left_HandFingerOneKnuckleOneLink</parent>
        <axis>
          <xyz>0 0.866025 0.5</xyz>
          <limit>
            <lower>0</lower>
            <upper>2.44339</upper>
            <effort>1</effort>
            <velocity>3.27</velocity>
          </limit>
          <dynamics>
            <damping>0.05</damping>
            <friction>0</friction>
            <spring_reference>0</spring_reference>
            <spring_stiffness>0</spring_stiffness>
          </dynamics>
          <use_parent_model_frame>1</use_parent_model_frame>
        </axis>
        <physics>
          <provide_feedback>1</provide_feedback>
          <ode>
            <provide_feedback>1</provide_feedback>
            <limit>
              <cfm>0</cfm>
              <erp>0.2</erp>
            </limit>
          </ode>
        </physics>
      </joint>
      <link name='left_HandFingerOneKnuckleThreeLink'>
        <pose frame=''>-0.12 0.879674 2.00098 -2.21358 -0.584233 -2.74989</pose>
        <inertial>
          <pose frame=''>0.01971 0.00182 0.0002 0 -0 0</pose>
          <mass>0.0342178</mass>
          <inertia>
            <ixx>4.61e-06</ixx>
            <ixy>3e-08</ixy>
            <ixz>1.64e-06</ixz>
            <iyy>3.59e-05</iyy>
            <iyz>4e-08</iyz>
            <izz>3.682e-05</izz>
          </inertia>
        </inertial>
        <collision name='left_HandFingerOneKnuckleThreeLink_collision'>
          <pose frame=''>0.025 0 0 0 -0 0</pose>
          <geometry>
            <box>
              <size>0.05 0.02 0.02</size>
            </box>
          </geometry>
          <surface>
            <contact>
              <ode/>
            </contact>
            <friction>
              <ode/>
            </friction>
          </surface>
          <max_contacts>10</max_contacts>
        </collision>
        <visual name='left_HandFingerOneKnuckleThreeLink_visual'>
          <pose frame=''>0 0 0 0 -0 0</pose>
          <geometry>
            <mesh>
              <scale>1 1 1</scale>
              <uri>/opt/ws_velma_os/share/barrett_hand_defs/meshes/thirdFingerOptoforceBaseLink.stl</uri>
            </mesh>
          </geometry>
          <material>
            <script>
              <uri>__default__</uri>
              <name>__default__</name>
            </script>
          </material>
        </visual>
        <gravity>1</gravity>
        <velocity_decay/>
        <self_collide>1</self_collide>
        <enable_wind>0</enable_wind>
      </link>
      <joint name='left_HandFingerOneKnuckleThreeJoint' type='revolute'>
        <child>left_HandFingerOneKnuckleThreeLink</child>
        <parent>left_HandFingerOneKnuckleTwoLink</parent>
        <axis>
          <xyz>0 0.866025 0.5</xyz>
          <limit>
            <lower>0</lower>
            <upper>0.837733</upper>
            <effort>1</effort>
            <velocity>3.27</velocity>
          </limit>
          <dynamics>
            <damping>0.05</damping>
            <friction>0</friction>
            <spring_reference>0</spring_reference>
            <spring_stiffness>0</spring_stiffness>
          </dynamics>
          <use_parent_model_frame>1</use_parent_model_frame>
        </axis>
        <physics>
          <provide_feedback>1</provide_feedback>
          <ode>
            <provide_feedback>1</provide_feedback>
            <limit>
              <cfm>0</cfm>
              <erp>0.2</erp>
            </limit>
          </ode>
        </physics>
      </joint>
      <link name='left_HandFingerOneKnuckleThreeOptoforceSensor'>
        <pose frame=''>-0.150223 0.862748 2.03029 -0.269479 -0.523599 1.5708</pose>
        <inertial>
          <pose frame=''>0 0 0 0 -0 0</pose>
          <mass>0.00342178</mass>
          <inertia>
            <ixx>2.87e-07</ixx>
            <ixy>9.1e-08</ixy>
            <ixz>-7e-09</ixz>
            <iyy>1.329e-06</iyy>
            <iyz>-2e-09</iyz>
            <izz>1.214e-06</izz>
          </inertia>
        </inertial>
        <collision name='left_HandFingerOneKnuckleThreeOptoforceSensor_collision'>
          <pose frame=''>0 0 0 0 -0 0</pose>
          <geometry>
            <sphere>
              <radius>0.01</radius>
            </sphere>
          </geometry>
          <surface>
            <contact>
              <ode/>
            </contact>
            <friction>
              <ode/>
            </friction>
          </surface>
          <max_contacts>10</max_contacts>
        </collision>
        <visual name='left_HandFingerOneKnuckleThreeOptoforceSensor_visual'>
          <pose frame=''>0 0 0 0 -0 0</pose>
          <geometry>
            <mesh>
              <scale>1 1 1</scale>
              <uri>/opt/ws_velma_os/share/barrett_hand_defs/meshes/optoforce_sphere.stl</uri>
            </mesh>
          </geometry>
          <material>
            <script>
              <uri>__default__</uri>
              <name>__default__</name>
            </script>
          </material>
        </visual>
        <gravity>1</gravity>
        <velocity_decay/>
        <self_collide>1</self_collide>
        <enable_wind>0</enable_wind>
      </link>
      <joint name='left_HandFingerOneKnuckleThreeOptoforceJoint' type='prismatic'>
        <child>left_HandFingerOneKnuckleThreeOptoforceSensor</child>
        <parent>left_HandFingerOneKnuckleThreeLink</parent>
        <axis>
          <xyz>-0.266229 -0.481955 0.83477</xyz>
          <limit>
            <lower>-0.005</lower>
            <upper>0.005</upper>
            <effort>2</effort>
            <velocity>0.1</velocity>
          </limit>
          <dynamics>
            <damping>0.1</damping>
            <friction>0</friction>
            <spring_reference>0</spring_reference>
            <spring_stiffness>0</spring_stiffness>
          </dynamics>
          <use_parent_model_frame>1</use_parent_model_frame>
        </axis>
        <physics>
          <provide_feedback>1</provide_feedback>
          <ode>
            <provide_feedback>1</provide_feedback>
            <limit>
              <cfm>0</cfm>
              <erp>0.2</erp>
            </limit>
          </ode>
        </physics>
      </joint>
      <link name='left_HandFingerThreeKnuckleTwoLink'>
        <pose frame=''>0.05 0.85805 1.98849 -1.0472 -0 -0</pose>
        <inertial>
          <pose frame=''>0.03172 0.00107 -0.000586 0 -0 0</pose>
          <mass>0.057957</mass>
          <inertia>
            <ixx>4.61e-06</ixx>
            <ixy>3e-08</ixy>
            <ixz>1.64e-06</ixz>
            <iyy>3.59e-05</iyy>
            <iyz>4e-08</iyz>
            <izz>3.682e-05</izz>
          </inertia>
        </inertial>
        <collision name='left_HandFingerThreeKnuckleTwoLink_collision'>
          <pose frame=''>0.03 0 0 0 -0 0</pose>
          <geometry>
            <box>
              <size>0.07 0.02 0.02</size>
            </box>
          </geometry>
          <surface>
            <contact>
              <ode/>
            </contact>
            <friction>
              <ode/>
            </friction>
          </surface>
          <max_contacts>10</max_contacts>
        </collision>
        <visual name='left_HandFingerThreeKnuckleTwoLink_visual'>
          <pose frame=''>0 0 0 3.14159 1.57079 3e-06</pose>
          <geometry>
            <mesh>
              <scale>1 1 1</scale>
              <uri>/opt/ws_velma_os/share/barrett_hand_defs/meshes/secondFingerLink.stl</uri>
            </mesh>
          </geometry>
          <material>
            <script>
              <uri>__default__</uri>
              <name>__default__</name>
            </script>
          </material>
        </visual>
        <gravity>1</gravity>
        <velocity_decay/>
        <self_collide>1</self_collide>
        <enable_wind>0</enable_wind>
      </link>
      <joint name='left_HandFingerThreeKnuckleTwoJoint' type='revolute'>
        <child>left_HandFingerThreeKnuckleTwoLink</child>
        <parent>left_FtSensorLink</parent>
        <axis>
          <xyz>0 -0.866025 -0.5</xyz>
          <limit>
            <lower>0</lower>
            <upper>2.44339</upper>
            <effort>1</effort>
            <velocity>3.27</velocity>
          </limit>
          <dynamics>
            <damping>0.05</damping>
            <friction>0</friction>
            <spring_reference>0</spring_reference>
            <spring_stiffness>0</spring_stiffness>
          </dynamics>
          <use_parent_model_frame>1</use_parent_model_frame>
        </axis>
        <physics>
          <provide_feedback>1</provide_feedback>
          <ode>
            <provide_feedback>1</provide_feedback>
            <limit>
              <cfm>0</cfm>
              <erp>0.2</erp>
            </limit>
          </ode>
        </physics>
      </joint>
      <link name='left_HandFingerThreeKnuckleThreeLink'>
        <pose frame=''>0.12 0.85805 1.98849 -0.928016 -0.584233 -0.391704</pose>
        <inertial>
          <pose frame=''>0.01971 0.00182 0.0002 0 -0 0</pose>
          <mass>0.0342178</mass>
          <inertia>
            <ixx>4.61e-06</ixx>
            <ixy>3e-08</ixy>
            <ixz>1.64e-06</ixz>
            <iyy>3.59e-05</iyy>
            <iyz>4e-08</iyz>
            <izz>3.682e-05</izz>
          </inertia>
        </inertial>
        <collision name='left_HandFingerThreeKnuckleThreeLink_collision'>
          <pose frame=''>0.025 0 0 0 -0 0</pose>
          <geometry>
            <box>
              <size>0.05 0.02 0.02</size>
            </box>
          </geometry>
          <surface>
            <contact>
              <ode/>
            </contact>
            <friction>
              <ode/>
            </friction>
          </surface>
          <max_contacts>10</max_contacts>
        </collision>
        <visual name='left_HandFingerThreeKnuckleThreeLink_visual'>
          <pose frame=''>0 0 0 0 -0 0</pose>
          <geometry>
            <mesh>
              <scale>1 1 1</scale>
              <uri>/opt/ws_velma_os/share/barrett_hand_defs/meshes/thirdFingerOptoforceBaseLink.stl</uri>
            </mesh>
          </geometry>
          <material>
            <script>
              <uri>__default__</uri>
              <name>__default__</name>
            </script>
          </material>
        </visual>
        <gravity>1</gravity>
        <velocity_decay/>
        <self_collide>1</self_collide>
        <enable_wind>0</enable_wind>
      </link>
      <joint name='left_HandFingerThreeKnuckleThreeJoint' type='revolute'>
        <child>left_HandFingerThreeKnuckleThreeLink</child>
        <parent>left_HandFingerThreeKnuckleTwoLink</parent>
        <axis>
          <xyz>0 -0.866025 -0.5</xyz>
          <limit>
            <lower>0</lower>
            <upper>0.837733</upper>
            <effort>1</effort>
            <velocity>3.27</velocity>
          </limit>
          <dynamics>
            <damping>0.05</damping>
            <friction>0</friction>
            <spring_reference>0</spring_reference>
            <spring_stiffness>0</spring_stiffness>
          </dynamics>
          <use_parent_model_frame>1</use_parent_model_frame>
        </axis>
        <physics>
          <provide_feedback>1</provide_feedback>
          <ode>
            <provide_feedback>1</provide_feedback>
            <limit>
              <cfm>0</cfm>
              <erp>0.2</erp>
            </limit>
          </ode>
        </physics>
      </joint>
      <link name='left_HandFingerThreeKnuckleThreeOptoforceSensor'>
        <pose frame=''>0.150223 0.841124 2.01781 -0.269479 0.523599 -1.5708</pose>
        <inertial>
          <pose frame=''>0 0 0 0 -0 0</pose>
          <mass>0.00342178</mass>
          <inertia>
            <ixx>2.87e-07</ixx>
            <ixy>9.1e-08</ixy>
            <ixz>-7e-09</ixz>
            <iyy>1.329e-06</iyy>
            <iyz>-2e-09</iyz>
            <izz>1.214e-06</izz>
          </inertia>
        </inertial>
        <collision name='left_HandFingerThreeKnuckleThreeOptoforceSensor_collision'>
          <pose frame=''>0 0 0 0 -0 0</pose>
          <geometry>
            <sphere>
              <radius>0.01</radius>
            </sphere>
          </geometry>
          <surface>
            <contact>
              <ode/>
            </contact>
            <friction>
              <ode/>
            </friction>
          </surface>
          <max_contacts>10</max_contacts>
        </collision>
        <visual name='left_HandFingerThreeKnuckleThreeOptoforceSensor_visual'>
          <pose frame=''>0 0 0 0 -0 0</pose>
          <geometry>
            <mesh>
              <scale>1 1 1</scale>
              <uri>/opt/ws_velma_os/share/barrett_hand_defs/meshes/optoforce_sphere.stl</uri>
            </mesh>
          </geometry>
          <material>
            <script>
              <uri>__default__</uri>
              <name>__default__</name>
            </script>
          </material>
        </visual>
        <gravity>1</gravity>
        <velocity_decay/>
        <self_collide>1</self_collide>
        <enable_wind>0</enable_wind>
      </link>
      <joint name='left_HandFingerThreeKnuckleThreeOptoforceJoint' type='prismatic'>
        <child>left_HandFingerThreeKnuckleThreeOptoforceSensor</child>
        <parent>left_HandFingerThreeKnuckleThreeLink</parent>
        <axis>
          <xyz>0.266229 -0.481955 0.83477</xyz>
          <limit>
            <lower>-0.005</lower>
            <upper>0.005</upper>
            <effort>2</effort>
            <velocity>0.1</velocity>
          </limit>
          <dynamics>
            <damping>0.1</damping>
            <friction>0</friction>
            <spring_reference>0</spring_reference>
            <spring_stiffness>0</spring_stiffness>
          </dynamics>
          <use_parent_model_frame>1</use_parent_model_frame>
        </axis>
        <physics>
          <provide_feedback>1</provide_feedback>
          <ode>
            <provide_feedback>1</provide_feedback>
            <limit>
              <cfm>0</cfm>
              <erp>0.2</erp>
            </limit>
          </ode>
        </physics>
      </joint>
      <link name='left_HandFingerTwoKnuckleOneLink'>
        <pose frame=''>0 0.844727 1.96163 -0.523599 0 3.14159</pose>
        <inertial>
          <pose frame=''>0.032017 -0.000865 0.008901 0 -0 0</pose>
          <mass>0.162527</mass>
          <inertia>
            <ixx>2.567e-05</ixx>
            <ixy>-1.46e-06</ixy>
            <ixz>1.128e-05</ixz>
            <iyy>8.818e-05</iyy>
            <iyz>-9.4e-07</iyz>
            <izz>7.827e-05</izz>
          </inertia>
        </inertial>
        <collision name='left_HandFingerTwoKnuckleOneLink_collision'>
          <pose frame=''>0 0 -0.0045 1.5708 0 -1.5708</pose>
          <geometry>
            <mesh>
              <scale>1 1 1</scale>
              <uri>/opt/ws_velma_os/share/barrett_hand_defs/meshes/firstFingerLink.stl</uri>
            </mesh>
          </geometry>
          <surface>
            <contact>
              <ode/>
            </contact>
            <friction>
              <ode/>
            </friction>
          </surface>
          <max_contacts>10</max_contacts>
        </collision>
        <visual name='left_HandFingerTwoKnuckleOneLink_visual'>
          <pose frame=''>0 0 -0.0045 1.5708 0 -1.5708</pose>
          <geometry>
            <mesh>
              <scale>1 1 1</scale>
              <uri>/opt/ws_velma_os/share/barrett_hand_defs/meshes/firstFingerLink.stl</uri>
            </mesh>
          </geometry>
          <material>
            <script>
              <uri>__default__</uri>
              <name>__default__</name>
            </script>
          </material>
        </visual>
        <gravity>1</gravity>
        <velocity_decay/>
        <self_collide>1</self_collide>
        <enable_wind>0</enable_wind>
      </link>
      <joint name='left_HandFingerTwoKnuckleOneJoint' type='revolute'>
        <child>left_HandFingerTwoKnuckleOneLink</child>
        <parent>left_FtSensorLink</parent>
        <axis>
          <xyz>-0 -0.5 0.866025</xyz>
          <limit>
            <lower>0</lower>
            <upper>3.14159</upper>
            <effort>1</effort>
            <velocity>3.27</velocity>
          </limit>
          <dynamics>
            <damping>0.1</damping>
            <friction>0</friction>
            <spring_reference>0</spring_reference>
            <spring_stiffness>0</spring_stiffness>
          </dynamics>
          <use_parent_model_frame>1</use_parent_model_frame>
        </axis>
        <physics>
          <provide_feedback>1</provide_feedback>
          <ode>
            <provide_feedback>1</provide_feedback>
            <limit>
              <cfm>0</cfm>
              <erp>0.2</erp>
            </limit>
          </ode>
        </physics>
      </joint>
      <link name='left_HandFingerTwoKnuckleTwoLink'>
        <pose frame=''>-0.05 0.836425 1.97601 -2.0944 -0 3.14159</pose>
        <inertial>
          <pose frame=''>0.03172 0.00107 -0.000586 0 -0 0</pose>
          <mass>0.057957</mass>
          <inertia>
            <ixx>4.61e-06</ixx>
            <ixy>3e-08</ixy>
            <ixz>1.64e-06</ixz>
            <iyy>3.59e-05</iyy>
            <iyz>4e-08</iyz>
            <izz>3.682e-05</izz>
          </inertia>
        </inertial>
        <collision name='left_HandFingerTwoKnuckleTwoLink_collision'>
          <pose frame=''>0.03 0 0 0 -0 0</pose>
          <geometry>
            <box>
              <size>0.07 0.02 0.02</size>
            </box>
          </geometry>
          <surface>
            <contact>
              <ode/>
            </contact>
            <friction>
              <ode/>
            </friction>
          </surface>
          <max_contacts>10</max_contacts>
        </collision>
        <visual name='left_HandFingerTwoKnuckleTwoLink_visual'>
          <pose frame=''>0 0 0 3.14159 1.57079 3e-06</pose>
          <geometry>
            <mesh>
              <scale>1 1 1</scale>
              <uri>/opt/ws_velma_os/share/barrett_hand_defs/meshes/secondFingerLink.stl</uri>
            </mesh>
          </geometry>
          <material>
            <script>
              <uri>__default__</uri>
              <name>__default__</name>
            </script>
          </material>
        </visual>
        <gravity>1</gravity>
        <velocity_decay/>
        <self_collide>1</self_collide>
        <enable_wind>0</enable_wind>
      </link>
      <joint name='left_HandFingerTwoKnuckleTwoJoint' type='revolute'>
        <child>left_HandFingerTwoKnuckleTwoLink</child>
        <parent>left_HandFingerTwoKnuckleOneLink</parent>
        <axis>
          <xyz>0 0.866025 0.5</xyz>
          <limit>
            <lower>0</lower>
            <upper>2.44339</upper>
            <effort>1</effort>
            <velocity>3.27</velocity>
          </limit>
          <dynamics>
            <damping>0.05</damping>
            <friction>0</friction>
            <spring_reference>0</spring_reference>
            <spring_stiffness>0</spring_stiffness>
          </dynamics>
          <use_parent_model_frame>1</use_parent_model_frame>
        </axis>
        <physics>
          <provide_feedback>1</provide_feedback>
          <ode>
            <provide_feedback>1</provide_feedback>
            <limit>
              <cfm>0</cfm>
              <erp>0.2</erp>
            </limit>
          </ode>
        </physics>
      </joint>
      <link name='left_HandFingerTwoKnuckleThreeLink'>
        <pose frame=''>-0.12 0.836425 1.97601 -2.21358 -0.584233 -2.74989</pose>
        <inertial>
          <pose frame=''>0.01971 0.00182 0.0002 0 -0 0</pose>
          <mass>0.0342178</mass>
          <inertia>
            <ixx>4.61e-06</ixx>
            <ixy>3e-08</ixy>
            <ixz>1.64e-06</ixz>
            <iyy>3.59e-05</iyy>
            <iyz>4e-08</iyz>
            <izz>3.682e-05</izz>
          </inertia>
        </inertial>
        <collision name='left_HandFingerTwoKnuckleThreeLink_collision'>
          <pose frame=''>0.025 0 0 0 -0 0</pose>
          <geometry>
            <box>
              <size>0.05 0.02 0.02</size>
            </box>
          </geometry>
          <surface>
            <contact>
              <ode/>
            </contact>
            <friction>
              <ode/>
            </friction>
          </surface>
          <max_contacts>10</max_contacts>
        </collision>
        <visual name='left_HandFingerTwoKnuckleThreeLink_visual'>
          <pose frame=''>0 0 0 0 -0 0</pose>
          <geometry>
            <mesh>
              <scale>1 1 1</scale>
              <uri>/opt/ws_velma_os/share/barrett_hand_defs/meshes/thirdFingerOptoforceBaseLink.stl</uri>
            </mesh>
          </geometry>
          <material>
            <script>
              <uri>__default__</uri>
              <name>__default__</name>
            </script>
          </material>
        </visual>
        <gravity>1</gravity>
        <velocity_decay/>
        <self_collide>1</self_collide>
        <enable_wind>0</enable_wind>
      </link>
      <joint name='left_HandFingerTwoKnuckleThreeJoint' type='revolute'>
        <child>left_HandFingerTwoKnuckleThreeLink</child>
        <parent>left_HandFingerTwoKnuckleTwoLink</parent>
        <axis>
          <xyz>0 0.866025 0.5</xyz>
          <limit>
            <lower>0</lower>
            <upper>0.837733</upper>
            <effort>1</effort>
            <velocity>3.27</velocity>
          </limit>
          <dynamics>
            <damping>0.05</damping>
            <friction>0</friction>
            <spring_reference>0</spring_reference>
            <spring_stiffness>0</spring_stiffness>
          </dynamics>
          <use_parent_model_frame>1</use_parent_model_frame>
        </axis>
        <physics>
          <provide_feedback>1</provide_feedback>
          <ode>
            <provide_feedback>1</provide_feedback>
            <limit>
              <cfm>0</cfm>
              <erp>0.2</erp>
            </limit>
          </ode>
        </physics>
      </joint>
      <link name='left_HandFingerTwoKnuckleThreeOptoforceSensor'>
        <pose frame=''>-0.150223 0.819499 2.00532 -0.269479 -0.523599 1.5708</pose>
        <inertial>
          <pose frame=''>0 0 0 0 -0 0</pose>
          <mass>0.00342178</mass>
          <inertia>
            <ixx>2.87e-07</ixx>
            <ixy>9.1e-08</ixy>
            <ixz>-7e-09</ixz>
            <iyy>1.329e-06</iyy>
            <iyz>-2e-09</iyz>
            <izz>1.214e-06</izz>
          </inertia>
        </inertial>
        <collision name='left_HandFingerTwoKnuckleThreeOptoforceSensor_collision'>
          <pose frame=''>0 0 0 0 -0 0</pose>
          <geometry>
            <sphere>
              <radius>0.01</radius>
            </sphere>
          </geometry>
          <surface>
            <contact>
              <ode/>
            </contact>
            <friction>
              <ode/>
            </friction>
          </surface>
          <max_contacts>10</max_contacts>
        </collision>
        <visual name='left_HandFingerTwoKnuckleThreeOptoforceSensor_visual'>
          <pose frame=''>0 0 0 0 -0 0</pose>
          <geometry>
            <mesh>
              <scale>1 1 1</scale>
              <uri>/opt/ws_velma_os/share/barrett_hand_defs/meshes/optoforce_sphere.stl</uri>
            </mesh>
          </geometry>
          <material>
            <script>
              <uri>__default__</uri>
              <name>__default__</name>
            </script>
          </material>
        </visual>
        <gravity>1</gravity>
        <velocity_decay/>
        <self_collide>1</self_collide>
        <enable_wind>0</enable_wind>
      </link>
      <joint name='left_HandFingerTwoKnuckleThreeOptoforceJoint' type='prismatic'>
        <child>left_HandFingerTwoKnuckleThreeOptoforceSensor</child>
        <parent>left_HandFingerTwoKnuckleThreeLink</parent>
        <axis>
          <xyz>-0.266229 -0.481955 0.83477</xyz>
          <limit>
            <lower>-0.005</lower>
            <upper>0.005</upper>
            <effort>2</effort>
            <velocity>0.1</velocity>
          </limit>
          <dynamics>
            <damping>0.1</damping>
            <friction>0</friction>
            <spring_reference>0</spring_reference>
            <spring_stiffness>0</spring_stiffness>
          </dynamics>
          <use_parent_model_frame>1</use_parent_model_frame>
        </axis>
        <physics>
          <provide_feedback>1</provide_feedback>
          <ode>
            <provide_feedback>1</provide_feedback>
            <limit>
              <cfm>0</cfm>
              <erp>0.2</erp>
            </limit>
          </ode>
        </physics>
      </joint>
      <link name='right_arm_1_link'>
        <pose frame=''>-0 -0.095452 1.32835 -0 -1.0472 1.5708</pose>
        <inertial>
          <pose frame=''>0 -0.06 0.13 0 -0 0</pose>
          <mass>2</mass>
          <inertia>
            <ixx>0.0136667</ixx>
            <ixy>0</ixy>
            <ixz>0</ixz>
            <iyy>0.003</iyy>
            <iyz>0</iyz>
            <izz>0.0118667</izz>
          </inertia>
        </inertial>
        <collision name='right_arm_1_link_collision'>
          <pose frame=''>0 0 0 0 -0 0</pose>
          <geometry>
            <mesh>
              <scale>1 1 1</scale>
              <uri>/opt/ws_velma_os/share/lwr_defs/meshes/lwr/convex/arm_segment_a_convex.stl</uri>
            </mesh>
          </geometry>
          <surface>
            <contact>
              <ode/>
            </contact>
            <friction>
              <ode/>
            </friction>
          </surface>
          <max_contacts>10</max_contacts>
        </collision>
        <visual name='right_arm_1_link_visual'>
          <pose frame=''>0 0 -0.008 0 -0 0</pose>
          <geometry>
            <mesh>
              <scale>1 1 1</scale>
              <uri>/opt/ws_velma_os/share/lwr_defs/meshes/lwr/link_1_simplified.STL</uri>
            </mesh>
          </geometry>
          <material>
            <script>
              <uri>__default__</uri>
              <name>__default__</name>
            </script>
          </material>
        </visual>
        <gravity>1</gravity>
        <velocity_decay/>
        <self_collide>1</self_collide>
        <enable_wind>0</enable_wind>
      </link>
      <joint name='right_arm_0_joint' type='revolute'>
        <child>right_arm_1_link</child>
        <parent>torso_link0</parent>
        <axis>
          <xyz>-0 -0.866025 0.5</xyz>
          <limit>
            <lower>-2.96706</lower>
            <upper>2.96706</upper>
            <effort>204</effort>
            <velocity>1.91986</velocity>
          </limit>
          <dynamics>
            <damping>1</damping>
            <friction>0</friction>
            <spring_reference>0</spring_reference>
            <spring_stiffness>0</spring_stiffness>
          </dynamics>
          <use_parent_model_frame>1</use_parent_model_frame>
        </axis>
      </joint>
      <link name='right_arm_2_link'>
        <pose frame=''>-0 -0.26909 1.4286 -0 -1.0472 1.5708</pose>
        <inertial>
          <pose frame=''>0 0.06 0.07 0 -0 0</pose>
          <mass>2</mass>
          <inertia>
            <ixx>0.0136667</ixx>
            <ixy>0</ixy>
            <ixz>0</ixz>
            <iyy>0.003</iyy>
            <iyz>0</iyz>
            <izz>0.0118667</izz>
          </inertia>
        </inertial>
        <collision name='right_arm_2_link_collision'>
          <pose frame=''>0 0 0.2 -3.14159 -0 0</pose>
          <geometry>
            <mesh>
              <scale>1 1 1</scale>
              <uri>/opt/ws_velma_os/share/lwr_defs/meshes/lwr/convex/arm_segment_b_convex.stl</uri>
            </mesh>
          </geometry>
          <surface>
            <contact>
              <ode/>
            </contact>
            <friction>
              <ode/>
            </friction>
          </surface>
          <max_contacts>10</max_contacts>
        </collision>
        <visual name='right_arm_2_link_visual'>
          <pose frame=''>0 0 0 0 -0 0</pose>
          <geometry>
            <mesh>
              <scale>1 1 1</scale>
              <uri>/opt/ws_velma_os/share/lwr_defs/meshes/lwr/link_2_simplified.STL</uri>
            </mesh>
          </geometry>
          <material>
            <script>
              <uri>__default__</uri>
              <name>__default__</name>
            </script>
          </material>
        </visual>
        <gravity>1</gravity>
        <velocity_decay/>
        <self_collide>1</self_collide>
        <enable_wind>0</enable_wind>
      </link>
      <joint name='right_arm_1_joint' type='revolute'>
        <child>right_arm_2_link</child>
        <parent>right_arm_1_link</parent>
        <axis>
          <xyz>-1 0 -0</xyz>
          <limit>
            <lower>-2.0944</lower>
            <upper>2.0944</upper>
            <effort>306</effort>
            <velocity>1.91986</velocity>
          </limit>
          <dynamics>
            <damping>1</damping>
            <friction>0</friction>
            <spring_reference>0</spring_reference>
            <spring_stiffness>0</spring_stiffness>
          </dynamics>
          <use_parent_model_frame>1</use_parent_model_frame>
        </axis>
      </joint>
      <link name='right_arm_3_link'>
        <pose frame=''>-0 -0.442295 1.5286 -0 -1.0472 1.5708</pose>
        <inertial>
          <pose frame=''>0 0.06 0.13 0 -0 0</pose>
          <mass>2</mass>
          <inertia>
            <ixx>0.0136667</ixx>
            <ixy>0</ixy>
            <ixz>0</ixz>
            <iyy>0.003</iyy>
            <iyz>0</iyz>
            <izz>0.0118667</izz>
          </inertia>
        </inertial>
        <collision name='right_arm_3_link_collision'>
          <pose frame=''>0 0 0 0 -0 -3.14159</pose>
          <geometry>
            <mesh>
              <scale>1 1 1</scale>
              <uri>/opt/ws_velma_os/share/lwr_defs/meshes/lwr/convex/arm_segment_a_convex.stl</uri>
            </mesh>
          </geometry>
          <surface>
            <contact>
              <ode/>
            </contact>
            <friction>
              <ode/>
            </friction>
          </surface>
          <max_contacts>10</max_contacts>
        </collision>
        <visual name='right_arm_3_link_visual'>
          <pose frame=''>0 0 -0.008 0 -0 0</pose>
          <geometry>
            <mesh>
              <scale>1 1 1</scale>
              <uri>/opt/ws_velma_os/share/lwr_defs/meshes/lwr/link_3_simplified.STL</uri>
            </mesh>
          </geometry>
          <material>
            <script>
              <uri>__default__</uri>
              <name>__default__</name>
            </script>
          </material>
        </visual>
        <gravity>1</gravity>
        <velocity_decay/>
        <self_collide>1</self_collide>
        <enable_wind>0</enable_wind>
      </link>
      <joint name='right_arm_2_joint' type='revolute'>
        <child>right_arm_3_link</child>
        <parent>right_arm_2_link</parent>
        <axis>
          <xyz>-0 -0.866025 0.5</xyz>
          <limit>
            <lower>-2.96706</lower>
            <upper>2.96706</upper>
            <effort>204</effort>
            <velocity>2.26893</velocity>
          </limit>
          <dynamics>
            <damping>1</damping>
            <friction>0</friction>
            <spring_reference>0</spring_reference>
            <spring_stiffness>0</spring_stiffness>
          </dynamics>
          <use_parent_model_frame>1</use_parent_model_frame>
        </axis>
      </joint>
      <link name='right_arm_4_link'>
        <pose frame=''>-0 -0.6155 1.6286 -0 -1.0472 1.5708</pose>
        <inertial>
          <pose frame=''>0 -0.06 0.07 0 -0 0</pose>
          <mass>2</mass>
          <inertia>
            <ixx>0.0136667</ixx>
            <ixy>0</ixy>
            <ixz>0</ixz>
            <iyy>0.003</iyy>
            <iyz>0</iyz>
            <izz>0.0118667</izz>
          </inertia>
        </inertial>
        <collision name='right_arm_4_link_collision'>
          <pose frame=''>0 0 0.2 3.14159 -0 3.14159</pose>
          <geometry>
            <mesh>
              <scale>1 1 1</scale>
              <uri>/opt/ws_velma_os/share/lwr_defs/meshes/lwr/convex/arm_segment_b_convex.stl</uri>
            </mesh>
          </geometry>
          <surface>
            <contact>
              <ode/>
            </contact>
            <friction>
              <ode/>
            </friction>
          </surface>
          <max_contacts>10</max_contacts>
        </collision>
        <visual name='right_arm_4_link_visual'>
          <pose frame=''>0 0 0 0 -0 0</pose>
          <geometry>
            <mesh>
              <scale>1 1 1</scale>
              <uri>/opt/ws_velma_os/share/lwr_defs/meshes/lwr/link_4_simplified.STL</uri>
            </mesh>
          </geometry>
          <material>
            <script>
              <uri>__default__</uri>
              <name>__default__</name>
            </script>
          </material>
        </visual>
        <gravity>1</gravity>
        <velocity_decay/>
        <self_collide>1</self_collide>
        <enable_wind>0</enable_wind>
      </link>
      <joint name='right_arm_3_joint' type='revolute'>
        <child>right_arm_4_link</child>
        <parent>right_arm_3_link</parent>
        <axis>
          <xyz>1 -0 0</xyz>
          <limit>
            <lower>-2.0944</lower>
            <upper>2.0944</upper>
            <effort>306</effort>
            <velocity>2.26893</velocity>
          </limit>
          <dynamics>
            <damping>1</damping>
            <friction>0</friction>
            <spring_reference>0</spring_reference>
            <spring_stiffness>0</spring_stiffness>
          </dynamics>
          <use_parent_model_frame>1</use_parent_model_frame>
        </axis>
      </joint>
      <link name='right_arm_5_link'>
        <pose frame=''>-0 -0.788705 1.7286 -0 -1.0472 1.5708</pose>
        <inertial>
          <pose frame=''>0 0 0.124 0 -0 0</pose>
          <mass>2</mass>
          <inertia>
            <ixx>0.0126507</ixx>
            <ixy>0</ixy>
            <ixz>0</ixz>
            <iyy>0.003</iyy>
            <iyz>0</iyz>
            <izz>0.0108507</izz>
          </inertia>
        </inertial>
        <collision name='right_arm_5_link_collision'>
          <pose frame=''>0 0 0 0 -0 0</pose>
          <geometry>
            <mesh>
              <scale>1 1 1</scale>
              <uri>/opt/ws_velma_os/share/lwr_defs/meshes/lwr/convex/arm_segment_last_convex.stl</uri>
            </mesh>
          </geometry>
          <surface>
            <contact>
              <ode/>
            </contact>
            <friction>
              <ode/>
            </friction>
          </surface>
          <max_contacts>10</max_contacts>
        </collision>
        <visual name='right_arm_5_link_visual'>
          <pose frame=''>0 0 -0.008 0 -0 0</pose>
          <geometry>
            <mesh>
              <scale>1 1 1</scale>
              <uri>/opt/ws_velma_os/share/lwr_defs/meshes/lwr/link_5_simplified.STL</uri>
            </mesh>
          </geometry>
          <material>
            <script>
              <uri>__default__</uri>
              <name>__default__</name>
            </script>
          </material>
        </visual>
        <gravity>1</gravity>
        <velocity_decay/>
        <self_collide>1</self_collide>
        <enable_wind>0</enable_wind>
      </link>
      <joint name='right_arm_4_joint' type='revolute'>
        <child>right_arm_5_link</child>
        <parent>right_arm_4_link</parent>
        <axis>
          <xyz>-0 -0.866025 0.5</xyz>
          <limit>
            <lower>-2.96706</lower>
            <upper>2.96706</upper>
            <effort>204</effort>
            <velocity>2.26893</velocity>
          </limit>
          <dynamics>
            <damping>1</damping>
            <friction>0</friction>
            <spring_reference>0</spring_reference>
            <spring_stiffness>0</spring_stiffness>
          </dynamics>
          <use_parent_model_frame>1</use_parent_model_frame>
        </axis>
      </joint>
      <link name='right_arm_6_link'>
        <pose frame=''>-0 -0.95325 1.8236 -0 -1.0472 1.5708</pose>
        <inertial>
          <pose frame=''>0 0 0.0625 0 -0 0</pose>
          <mass>0.2</mass>
          <inertia>
            <ixx>0.000520833</ixx>
            <ixy>0</ixy>
            <ixz>0</ixz>
            <iyy>0.000520833</iyy>
            <iyz>0</iyz>
            <izz>0.000520833</izz>
          </inertia>
        </inertial>
        <collision name='right_arm_6_link_collision'>
          <pose frame=''>0 0 0 0 -0 0</pose>
          <geometry>
            <mesh>
              <scale>1 1 1</scale>
              <uri>/opt/ws_velma_os/share/lwr_defs/meshes/lwr/convex/arm_wrist_convex.stl</uri>
            </mesh>
          </geometry>
          <surface>
            <contact>
              <ode/>
            </contact>
            <friction>
              <ode/>
            </friction>
          </surface>
          <max_contacts>10</max_contacts>
        </collision>
        <visual name='right_arm_6_link_visual'>
          <pose frame=''>0 0 0 0 -0 0</pose>
          <geometry>
            <mesh>
              <scale>1 1 1</scale>
              <uri>/opt/ws_velma_os/share/lwr_defs/meshes/lwr/link_6_simplified.STL</uri>
            </mesh>
          </geometry>
          <material>
            <script>
              <uri>__default__</uri>
              <name>__default__</name>
            </script>
          </material>
        </visual>
        <gravity>1</gravity>
        <velocity_decay/>
        <self_collide>1</self_collide>
        <enable_wind>0</enable_wind>
      </link>
      <joint name='right_arm_5_joint' type='revolute'>
        <child>right_arm_6_link</child>
        <parent>right_arm_5_link</parent>
        <axis>
          <xyz>-1 0 -0</xyz>
          <limit>
            <lower>-2.0944</lower>
            <upper>2.0944</upper>
            <effort>306</effort>
            <velocity>3.14159</velocity>
          </limit>
          <dynamics>
            <damping>1</damping>
            <friction>0</friction>
            <spring_reference>0</spring_reference>
            <spring_stiffness>0</spring_stiffness>
          </dynamics>
          <use_parent_model_frame>1</use_parent_model_frame>
        </axis>
      </joint>
      <link name='right_arm_7_link'>
        <pose frame=''>-0 -1.0208 1.8626 -0 -1.0472 1.5708</pose>
        <inertial>
          <pose frame=''>0.05398 3.1e-05 -0.031139 0 -0 0</pose>
          <mass>0.291212</mass>
          <inertia>
            <ixx>0.00107689</ixx>
            <ixy>-3.40075e-09</ixy>
            <ixz>0.00056961</ixz>
            <iyy>0.00170618</iyy>
            <iyz>1.96175e-09</iyz>
            <izz>0.0012739</izz>
          </inertia>
        </inertial>
        <collision name='right_arm_7_link_fixed_joint_lump__right_gripper_mount_link_collision'>
          <pose frame=''>0 0 0 0 -0 0</pose>
          <geometry>
            <mesh>
              <scale>1 1 1</scale>
              <uri>/opt/ws_velma_os/share/velma_description/meshes/collision/gripper_mount_collision2.STL</uri>
            </mesh>
          </geometry>
          <surface>
            <contact>
              <ode/>
            </contact>
            <friction>
              <ode/>
            </friction>
          </surface>
          <max_contacts>10</max_contacts>
        </collision>
        <visual name='right_arm_7_link_visual'>
          <pose frame=''>0 0 0 0 -0 0</pose>
          <geometry>
            <mesh>
              <scale>1 1 1</scale>
              <uri>/opt/ws_velma_os/share/lwr_defs/meshes/lwr/link_7_simplified.STL</uri>
            </mesh>
          </geometry>
          <material>
            <script>
              <uri>__default__</uri>
              <name>__default__</name>
            </script>
          </material>
        </visual>
        <visual name='right_arm_7_link_fixed_joint_lump__right_gripper_mount_link_visual_1'>
          <pose frame=''>0 0 0 0 -0 0</pose>
          <geometry>
            <mesh>
              <scale>1 1 1</scale>
              <uri>/opt/ws_velma_os/share/velma_description/meshes/gripper_mount_simplified.stl</uri>
            </mesh>
          </geometry>
          <material>
            <script>
              <uri>__default__</uri>
              <name>__default__</name>
            </script>
          </material>
        </visual>
        <visual name='right_arm_7_link_fixed_joint_lump__right_gripper_mount_link_visual_2'>
          <pose frame=''>0 0 0 0 -0 0</pose>
          <geometry>
            <mesh>
              <scale>1 1 1</scale>
              <uri>/opt/ws_velma_os/share/velma_description/meshes/imu_case_right.stl</uri>
            </mesh>
          </geometry>
          <material>
            <script>
              <uri>__default__</uri>
              <name>__default__</name>
            </script>
          </material>
        </visual>
        <velocity_decay/>
        <gravity>1</gravity>
        <velocity_decay/>
        <self_collide>1</self_collide>
        <enable_wind>0</enable_wind>
      </link>
      <joint name='right_arm_6_joint' type='revolute'>
        <child>right_arm_7_link</child>
        <parent>right_arm_6_link</parent>
        <axis>
          <xyz>-0 -0.866025 0.5</xyz>
          <limit>
            <lower>-2.96706</lower>
            <upper>2.96706</upper>
            <effort>204</effort>
            <velocity>3.14159</velocity>
          </limit>
          <dynamics>
            <damping>1</damping>
            <friction>0</friction>
            <spring_reference>0</spring_reference>
            <spring_stiffness>0</spring_stiffness>
          </dynamics>
          <use_parent_model_frame>1</use_parent_model_frame>
        </axis>
        <physics>
          <provide_feedback>1</provide_feedback>
          <ode>
            <provide_feedback>1</provide_feedback>
            <limit>
              <cfm>0</cfm>
              <erp>0.2</erp>
            </limit>
          </ode>
        </physics>
      </joint>
      <link name='right_FtSensorLink'>
        <pose frame=''>-0 -0.89575 1.92319 0 0.523599 1.5708</pose>
        <inertial>
          <pose frame=''>0.000354 -0.004974 0.048497 0 -0 0</pose>
          <mass>0.635529</mass>
          <inertia>
            <ixx>0.00103101</ixx>
            <ixy>7.75353e-06</ixy>
            <ixz>-1.23344e-05</ixz>
            <iyy>0.000819367</iyy>
            <iyz>-0.000143686</iyz>
            <izz>0.000693138</izz>
          </inertia>
        </inertial>
        <collision name='right_FtSensorLink_fixed_joint_lump__right_HandPalmLink_collision'>
          <pose frame=''>0 0 0 0 -0 0</pose>
          <geometry>
            <mesh>
              <scale>1 1 1</scale>
              <uri>/opt/ws_velma_os/share/barrett_hand_defs/meshes/palm.stl</uri>
            </mesh>
          </geometry>
          <surface>
            <contact>
              <ode/>
            </contact>
            <friction>
              <ode/>
            </friction>
          </surface>
          <max_contacts>10</max_contacts>
        </collision>
        <visual name='right_FtSensorLink_fixed_joint_lump__right_HandPalmLink_visual'>
          <pose frame=''>0 0 0 0 -0 0</pose>
          <geometry>
            <mesh>
              <scale>1 1 1</scale>
              <uri>/opt/ws_velma_os/share/barrett_hand_defs/meshes/palm.stl</uri>
            </mesh>
          </geometry>
          <material>
            <script>
              <uri>__default__</uri>
              <name>__default__</name>
            </script>
          </material>
        </visual>
        <velocity_decay/>
        <velocity_decay/>
        <gravity>1</gravity>
        <velocity_decay/>
        <self_collide>1</self_collide>
        <enable_wind>0</enable_wind>
      </link>
      <joint name='rightFtSensorJoint' type='revolute'>
        <child>right_FtSensorLink</child>
        <parent>right_arm_7_link</parent>
        <axis>
          <xyz>0 0.5 0.866025</xyz>
          <limit>
            <lower>0</lower>
            <upper>0</upper>
            <effort>10</effort>
            <velocity>3.27</velocity>
          </limit>
          <dynamics>
            <damping>0.05</damping>
            <friction>0</friction>
            <spring_reference>0</spring_reference>
            <spring_stiffness>0</spring_stiffness>
          </dynamics>
          <use_parent_model_frame>1</use_parent_model_frame>
        </axis>
        <physics>
          <provide_feedback>1</provide_feedback>
          <ode>
            <provide_feedback>1</provide_feedback>
            <limit>
              <cfm>0</cfm>
              <erp>0.2</erp>
            </limit>
          </ode>
        </physics>
      </joint>
      <link name='right_HandFingerOneKnuckleOneLink'>
        <pose frame=''>-0 -0.844727 1.96163 0.523599 -0 3.14159</pose>
        <inertial>
          <pose frame=''>0.032017 -0.000865 0.008901 0 -0 0</pose>
          <mass>0.162527</mass>
          <inertia>
            <ixx>2.567e-05</ixx>
            <ixy>-1.46e-06</ixy>
            <ixz>1.128e-05</ixz>
            <iyy>8.818e-05</iyy>
            <iyz>-9.4e-07</iyz>
            <izz>7.827e-05</izz>
          </inertia>
        </inertial>
        <collision name='right_HandFingerOneKnuckleOneLink_collision'>
          <pose frame=''>0 0 -0.0045 1.5708 0 -1.5708</pose>
          <geometry>
            <mesh>
              <scale>1 1 1</scale>
              <uri>/opt/ws_velma_os/share/barrett_hand_defs/meshes/firstFingerLink.stl</uri>
            </mesh>
          </geometry>
          <surface>
            <contact>
              <ode/>
            </contact>
            <friction>
              <ode/>
            </friction>
          </surface>
          <max_contacts>10</max_contacts>
        </collision>
        <visual name='right_HandFingerOneKnuckleOneLink_visual'>
          <pose frame=''>0 0 -0.0045 1.5708 0 -1.5708</pose>
          <geometry>
            <mesh>
              <scale>1 1 1</scale>
              <uri>/opt/ws_velma_os/share/barrett_hand_defs/meshes/firstFingerLink.stl</uri>
            </mesh>
          </geometry>
          <material>
            <script>
              <uri>__default__</uri>
              <name>__default__</name>
            </script>
          </material>
        </visual>
        <gravity>1</gravity>
        <velocity_decay/>
        <self_collide>1</self_collide>
        <enable_wind>0</enable_wind>
      </link>
      <joint name='right_HandFingerOneKnuckleOneJoint' type='revolute'>
        <child>right_HandFingerOneKnuckleOneLink</child>
        <parent>right_FtSensorLink</parent>
        <axis>
          <xyz>-0 -0.5 -0.866025</xyz>
          <limit>
            <lower>0</lower>
            <upper>3.14159</upper>
            <effort>1</effort>
            <velocity>3.27</velocity>
          </limit>
          <dynamics>
            <damping>0.1</damping>
            <friction>0</friction>
            <spring_reference>0</spring_reference>
            <spring_stiffness>0</spring_stiffness>
          </dynamics>
          <use_parent_model_frame>1</use_parent_model_frame>
        </axis>
        <physics>
          <provide_feedback>1</provide_feedback>
          <ode>
            <provide_feedback>1</provide_feedback>
            <limit>
              <cfm>0</cfm>
              <erp>0.2</erp>
            </limit>
          </ode>
        </physics>
      </joint>
      <link name='right_HandFingerOneKnuckleTwoLink'>
        <pose frame=''>-0.05 -0.836425 1.97601 -1.0472 0 3.14159</pose>
        <inertial>
          <pose frame=''>0.03172 0.00107 -0.000586 0 -0 0</pose>
          <mass>0.057957</mass>
          <inertia>
            <ixx>4.61e-06</ixx>
            <ixy>3e-08</ixy>
            <ixz>1.64e-06</ixz>
            <iyy>3.59e-05</iyy>
            <iyz>4e-08</iyz>
            <izz>3.682e-05</izz>
          </inertia>
        </inertial>
        <collision name='right_HandFingerOneKnuckleTwoLink_collision'>
          <pose frame=''>0.03 0 0 0 -0 0</pose>
          <geometry>
            <box>
              <size>0.07 0.02 0.02</size>
            </box>
          </geometry>
          <surface>
            <contact>
              <ode/>
            </contact>
            <friction>
              <ode/>
            </friction>
          </surface>
          <max_contacts>10</max_contacts>
        </collision>
        <visual name='right_HandFingerOneKnuckleTwoLink_visual'>
          <pose frame=''>0 0 0 3.14159 1.57079 3e-06</pose>
          <geometry>
            <mesh>
              <scale>1 1 1</scale>
              <uri>/opt/ws_velma_os/share/barrett_hand_defs/meshes/secondFingerLink.stl</uri>
            </mesh>
          </geometry>
          <material>
            <script>
              <uri>__default__</uri>
              <name>__default__</name>
            </script>
          </material>
        </visual>
        <gravity>1</gravity>
        <velocity_decay/>
        <self_collide>1</self_collide>
        <enable_wind>0</enable_wind>
      </link>
      <joint name='right_HandFingerOneKnuckleTwoJoint' type='revolute'>
        <child>right_HandFingerOneKnuckleTwoLink</child>
        <parent>right_HandFingerOneKnuckleOneLink</parent>
        <axis>
          <xyz>0 0.866025 -0.5</xyz>
          <limit>
            <lower>0</lower>
            <upper>2.44339</upper>
            <effort>1</effort>
            <velocity>3.27</velocity>
          </limit>
          <dynamics>
            <damping>0.05</damping>
            <friction>0</friction>
            <spring_reference>0</spring_reference>
            <spring_stiffness>0</spring_stiffness>
          </dynamics>
          <use_parent_model_frame>1</use_parent_model_frame>
        </axis>
        <physics>
          <provide_feedback>1</provide_feedback>
          <ode>
            <provide_feedback>1</provide_feedback>
            <limit>
              <cfm>0</cfm>
              <erp>0.2</erp>
            </limit>
          </ode>
        </physics>
      </joint>
      <link name='right_HandFingerOneKnuckleThreeLink'>
        <pose frame=''>-0.12 -0.836425 1.97601 -0.928016 -0.584233 2.74989</pose>
        <inertial>
          <pose frame=''>0.01971 0.00182 0.0002 0 -0 0</pose>
          <mass>0.0342178</mass>
          <inertia>
            <ixx>4.61e-06</ixx>
            <ixy>3e-08</ixy>
            <ixz>1.64e-06</ixz>
            <iyy>3.59e-05</iyy>
            <iyz>4e-08</iyz>
            <izz>3.682e-05</izz>
          </inertia>
        </inertial>
        <collision name='right_HandFingerOneKnuckleThreeLink_collision'>
          <pose frame=''>0.025 0 0 0 -0 0</pose>
          <geometry>
            <box>
              <size>0.05 0.02 0.02</size>
            </box>
          </geometry>
          <surface>
            <contact>
              <ode/>
            </contact>
            <friction>
              <ode/>
            </friction>
          </surface>
          <max_contacts>10</max_contacts>
        </collision>
        <visual name='right_HandFingerOneKnuckleThreeLink_visual'>
          <pose frame=''>0 0 0 0 -0 0</pose>
          <geometry>
            <mesh>
              <scale>1 1 1</scale>
              <uri>/opt/ws_velma_os/share/barrett_hand_defs/meshes/thirdFingerLink.stl</uri>
            </mesh>
          </geometry>
          <material>
            <script>
              <uri>__default__</uri>
              <name>__default__</name>
            </script>
          </material>
        </visual>
        <gravity>1</gravity>
        <velocity_decay/>
        <self_collide>1</self_collide>
        <enable_wind>0</enable_wind>
      </link>
      <joint name='right_HandFingerOneKnuckleThreeJoint' type='revolute'>
        <child>right_HandFingerOneKnuckleThreeLink</child>
        <parent>right_HandFingerOneKnuckleTwoLink</parent>
        <axis>
          <xyz>0 0.866025 -0.5</xyz>
          <limit>
            <lower>0</lower>
            <upper>0.837733</upper>
            <effort>1</effort>
            <velocity>3.27</velocity>
          </limit>
          <dynamics>
            <damping>0.05</damping>
            <friction>0</friction>
            <spring_reference>0</spring_reference>
            <spring_stiffness>0</spring_stiffness>
          </dynamics>
          <use_parent_model_frame>1</use_parent_model_frame>
        </axis>
        <physics>
          <provide_feedback>1</provide_feedback>
          <ode>
            <provide_feedback>1</provide_feedback>
            <limit>
              <cfm>0</cfm>
              <erp>0.2</erp>
            </limit>
          </ode>
        </physics>
      </joint>
      <link name='right_HandFingerThreeKnuckleTwoLink'>
        <pose frame=''>0.05 -0.85805 1.98849 -2.0944 0 0</pose>
        <inertial>
          <pose frame=''>0.03172 0.00107 -0.000586 0 -0 0</pose>
          <mass>0.057957</mass>
          <inertia>
            <ixx>4.61e-06</ixx>
            <ixy>3e-08</ixy>
            <ixz>1.64e-06</ixz>
            <iyy>3.59e-05</iyy>
            <iyz>4e-08</iyz>
            <izz>3.682e-05</izz>
          </inertia>
        </inertial>
        <collision name='right_HandFingerThreeKnuckleTwoLink_collision'>
          <pose frame=''>0.03 0 0 0 -0 0</pose>
          <geometry>
            <box>
              <size>0.07 0.02 0.02</size>
            </box>
          </geometry>
          <surface>
            <contact>
              <ode/>
            </contact>
            <friction>
              <ode/>
            </friction>
          </surface>
          <max_contacts>10</max_contacts>
        </collision>
        <visual name='right_HandFingerThreeKnuckleTwoLink_visual'>
          <pose frame=''>0 0 0 3.14159 1.57079 3e-06</pose>
          <geometry>
            <mesh>
              <scale>1 1 1</scale>
              <uri>/opt/ws_velma_os/share/barrett_hand_defs/meshes/secondFingerLink.stl</uri>
            </mesh>
          </geometry>
          <material>
            <script>
              <uri>__default__</uri>
              <name>__default__</name>
            </script>
          </material>
        </visual>
        <gravity>1</gravity>
        <velocity_decay/>
        <self_collide>1</self_collide>
        <enable_wind>0</enable_wind>
      </link>
      <joint name='right_HandFingerThreeKnuckleTwoJoint' type='revolute'>
        <child>right_HandFingerThreeKnuckleTwoLink</child>
        <parent>right_FtSensorLink</parent>
        <axis>
          <xyz>0 -0.866025 0.5</xyz>
          <limit>
            <lower>0</lower>
            <upper>2.44339</upper>
            <effort>1</effort>
            <velocity>3.27</velocity>
          </limit>
          <dynamics>
            <damping>0.05</damping>
            <friction>0</friction>
            <spring_reference>0</spring_reference>
            <spring_stiffness>0</spring_stiffness>
          </dynamics>
          <use_parent_model_frame>1</use_parent_model_frame>
        </axis>
        <physics>
          <provide_feedback>1</provide_feedback>
          <ode>
            <provide_feedback>1</provide_feedback>
            <limit>
              <cfm>0</cfm>
              <erp>0.2</erp>
            </limit>
          </ode>
        </physics>
      </joint>
      <link name='right_HandFingerThreeKnuckleThreeLink'>
        <pose frame=''>0.12 -0.85805 1.98849 -2.21358 -0.584233 0.391704</pose>
        <inertial>
          <pose frame=''>0.01971 0.00182 0.0002 0 -0 0</pose>
          <mass>0.0342178</mass>
          <inertia>
            <ixx>4.61e-06</ixx>
            <ixy>3e-08</ixy>
            <ixz>1.64e-06</ixz>
            <iyy>3.59e-05</iyy>
            <iyz>4e-08</iyz>
            <izz>3.682e-05</izz>
          </inertia>
        </inertial>
        <collision name='right_HandFingerThreeKnuckleThreeLink_collision'>
          <pose frame=''>0.025 0 0 0 -0 0</pose>
          <geometry>
            <box>
              <size>0.05 0.02 0.02</size>
            </box>
          </geometry>
          <surface>
            <contact>
              <ode/>
            </contact>
            <friction>
              <ode/>
            </friction>
          </surface>
          <max_contacts>10</max_contacts>
        </collision>
        <visual name='right_HandFingerThreeKnuckleThreeLink_visual'>
          <pose frame=''>0 0 0 0 -0 0</pose>
          <geometry>
            <mesh>
              <scale>1 1 1</scale>
              <uri>/opt/ws_velma_os/share/barrett_hand_defs/meshes/thirdFingerLink.stl</uri>
            </mesh>
          </geometry>
          <material>
            <script>
              <uri>__default__</uri>
              <name>__default__</name>
            </script>
          </material>
        </visual>
        <gravity>1</gravity>
        <velocity_decay/>
        <self_collide>1</self_collide>
        <enable_wind>0</enable_wind>
      </link>
      <joint name='right_HandFingerThreeKnuckleThreeJoint' type='revolute'>
        <child>right_HandFingerThreeKnuckleThreeLink</child>
        <parent>right_HandFingerThreeKnuckleTwoLink</parent>
        <axis>
          <xyz>0 -0.866025 0.5</xyz>
          <limit>
            <lower>0</lower>
            <upper>0.837733</upper>
            <effort>1</effort>
            <velocity>3.27</velocity>
          </limit>
          <dynamics>
            <damping>0.05</damping>
            <friction>0</friction>
            <spring_reference>0</spring_reference>
            <spring_stiffness>0</spring_stiffness>
          </dynamics>
          <use_parent_model_frame>1</use_parent_model_frame>
        </axis>
        <physics>
          <provide_feedback>1</provide_feedback>
          <ode>
            <provide_feedback>1</provide_feedback>
            <limit>
              <cfm>0</cfm>
              <erp>0.2</erp>
            </limit>
          </ode>
        </physics>
      </joint>
      <link name='right_HandFingerTwoKnuckleOneLink'>
        <pose frame=''>-0 -0.887976 1.9866 0.523599 -0 3.14159</pose>
        <inertial>
          <pose frame=''>0.032017 -0.000865 0.008901 0 -0 0</pose>
          <mass>0.162527</mass>
          <inertia>
            <ixx>2.567e-05</ixx>
            <ixy>-1.46e-06</ixy>
            <ixz>1.128e-05</ixz>
            <iyy>8.818e-05</iyy>
            <iyz>-9.4e-07</iyz>
            <izz>7.827e-05</izz>
          </inertia>
        </inertial>
        <collision name='right_HandFingerTwoKnuckleOneLink_collision'>
          <pose frame=''>0 0 -0.0045 1.5708 0 -1.5708</pose>
          <geometry>
            <mesh>
              <scale>1 1 1</scale>
              <uri>/opt/ws_velma_os/share/barrett_hand_defs/meshes/firstFingerLink.stl</uri>
            </mesh>
          </geometry>
          <surface>
            <contact>
              <ode/>
            </contact>
            <friction>
              <ode/>
            </friction>
          </surface>
          <max_contacts>10</max_contacts>
        </collision>
        <visual name='right_HandFingerTwoKnuckleOneLink_visual'>
          <pose frame=''>0 0 -0.0045 1.5708 0 -1.5708</pose>
          <geometry>
            <mesh>
              <scale>1 1 1</scale>
              <uri>/opt/ws_velma_os/share/barrett_hand_defs/meshes/firstFingerLink.stl</uri>
            </mesh>
          </geometry>
          <material>
            <script>
              <uri>__default__</uri>
              <name>__default__</name>
            </script>
          </material>
        </visual>
        <gravity>1</gravity>
        <velocity_decay/>
        <self_collide>1</self_collide>
        <enable_wind>0</enable_wind>
      </link>
      <joint name='right_HandFingerTwoKnuckleOneJoint' type='revolute'>
        <child>right_HandFingerTwoKnuckleOneLink</child>
        <parent>right_FtSensorLink</parent>
        <axis>
          <xyz>0 0.5 0.866025</xyz>
          <limit>
            <lower>0</lower>
            <upper>3.14159</upper>
            <effort>1</effort>
            <velocity>3.27</velocity>
          </limit>
          <dynamics>
            <damping>0.1</damping>
            <friction>0</friction>
            <spring_reference>0</spring_reference>
            <spring_stiffness>0</spring_stiffness>
          </dynamics>
          <use_parent_model_frame>1</use_parent_model_frame>
        </axis>
        <physics>
          <provide_feedback>1</provide_feedback>
          <ode>
            <provide_feedback>1</provide_feedback>
            <limit>
              <cfm>0</cfm>
              <erp>0.2</erp>
            </limit>
          </ode>
        </physics>
      </joint>
      <link name='right_HandFingerTwoKnuckleTwoLink'>
        <pose frame=''>-0.05 -0.879674 2.00098 -1.0472 0 3.14159</pose>
        <inertial>
          <pose frame=''>0.03172 0.00107 -0.000586 0 -0 0</pose>
          <mass>0.057957</mass>
          <inertia>
            <ixx>4.61e-06</ixx>
            <ixy>3e-08</ixy>
            <ixz>1.64e-06</ixz>
            <iyy>3.59e-05</iyy>
            <iyz>4e-08</iyz>
            <izz>3.682e-05</izz>
          </inertia>
        </inertial>
        <collision name='right_HandFingerTwoKnuckleTwoLink_collision'>
          <pose frame=''>0.03 0 0 0 -0 0</pose>
          <geometry>
            <box>
              <size>0.07 0.02 0.02</size>
            </box>
          </geometry>
          <surface>
            <contact>
              <ode/>
            </contact>
            <friction>
              <ode/>
            </friction>
          </surface>
          <max_contacts>10</max_contacts>
        </collision>
        <visual name='right_HandFingerTwoKnuckleTwoLink_visual'>
          <pose frame=''>0 0 0 3.14159 1.57079 3e-06</pose>
          <geometry>
            <mesh>
              <scale>1 1 1</scale>
              <uri>/opt/ws_velma_os/share/barrett_hand_defs/meshes/secondFingerLink.stl</uri>
            </mesh>
          </geometry>
          <material>
            <script>
              <uri>__default__</uri>
              <name>__default__</name>
            </script>
          </material>
        </visual>
        <gravity>1</gravity>
        <velocity_decay/>
        <self_collide>1</self_collide>
        <enable_wind>0</enable_wind>
      </link>
      <joint name='right_HandFingerTwoKnuckleTwoJoint' type='revolute'>
        <child>right_HandFingerTwoKnuckleTwoLink</child>
        <parent>right_HandFingerTwoKnuckleOneLink</parent>
        <axis>
          <xyz>0 0.866025 -0.5</xyz>
          <limit>
            <lower>0</lower>
            <upper>2.44339</upper>
            <effort>1</effort>
            <velocity>3.27</velocity>
          </limit>
          <dynamics>
            <damping>0.05</damping>
            <friction>0</friction>
            <spring_reference>0</spring_reference>
            <spring_stiffness>0</spring_stiffness>
          </dynamics>
          <use_parent_model_frame>1</use_parent_model_frame>
        </axis>
        <physics>
          <provide_feedback>1</provide_feedback>
          <ode>
            <provide_feedback>1</provide_feedback>
            <limit>
              <cfm>0</cfm>
              <erp>0.2</erp>
            </limit>
          </ode>
        </physics>
      </joint>
      <link name='right_HandFingerTwoKnuckleThreeLink'>
        <pose frame=''>-0.12 -0.879674 2.00098 -0.928016 -0.584233 2.74989</pose>
        <inertial>
          <pose frame=''>0.01971 0.00182 0.0002 0 -0 0</pose>
          <mass>0.0342178</mass>
          <inertia>
            <ixx>4.61e-06</ixx>
            <ixy>3e-08</ixy>
            <ixz>1.64e-06</ixz>
            <iyy>3.59e-05</iyy>
            <iyz>4e-08</iyz>
            <izz>3.682e-05</izz>
          </inertia>
        </inertial>
        <collision name='right_HandFingerTwoKnuckleThreeLink_collision'>
          <pose frame=''>0.025 0 0 0 -0 0</pose>
          <geometry>
            <box>
              <size>0.05 0.02 0.02</size>
            </box>
          </geometry>
          <surface>
            <contact>
              <ode/>
            </contact>
            <friction>
              <ode/>
            </friction>
          </surface>
          <max_contacts>10</max_contacts>
        </collision>
        <visual name='right_HandFingerTwoKnuckleThreeLink_visual'>
          <pose frame=''>0 0 0 0 -0 0</pose>
          <geometry>
            <mesh>
              <scale>1 1 1</scale>
              <uri>/opt/ws_velma_os/share/barrett_hand_defs/meshes/thirdFingerLink.stl</uri>
            </mesh>
          </geometry>
          <material>
            <script>
              <uri>__default__</uri>
              <name>__default__</name>
            </script>
          </material>
        </visual>
        <gravity>1</gravity>
        <velocity_decay/>
        <self_collide>1</self_collide>
        <enable_wind>0</enable_wind>
      </link>
      <joint name='right_HandFingerTwoKnuckleThreeJoint' type='revolute'>
        <child>right_HandFingerTwoKnuckleThreeLink</child>
        <parent>right_HandFingerTwoKnuckleTwoLink</parent>
        <axis>
          <xyz>0 0.866025 -0.5</xyz>
          <limit>
            <lower>0</lower>
            <upper>0.837733</upper>
            <effort>1</effort>
            <velocity>3.27</velocity>
          </limit>
          <dynamics>
            <damping>0.05</damping>
            <friction>0</friction>
            <spring_reference>0</spring_reference>
            <spring_stiffness>0</spring_stiffness>
          </dynamics>
          <use_parent_model_frame>1</use_parent_model_frame>
        </axis>
        <physics>
          <provide_feedback>1</provide_feedback>
          <ode>
            <provide_feedback>1</provide_feedback>
            <limit>
              <cfm>0</cfm>
              <erp>0.2</erp>
            </limit>
          </ode>
        </physics>
      </joint>
      <static>0</static>
      <plugin name='rtt_gazebo' filename='librtt_gazebo_deployer.so'>
        <isolated/>
        <subsystem_xml>
          <filename>/opt/ws_velma_os/share/velma_sim_gazebo/config/velma_core_re.xml</filename>
        </subsystem_xml>
        <master_service>
          <name>velma_sim_gazebo</name>
        </master_service>
        <component>
          <package>velma_sim_gazebo</package>
          <type>TorsoGazebo</type>
          <name>TorsoSim</name>
        </component>
        <component>
          <package>velma_sim_gazebo</package>
          <type>LWRGazebo</type>
          <name>LWRrSim</name>
        </component>
        <component>
          <package>velma_sim_gazebo</package>
          <type>LWRGazebo</type>
          <name>LWRlSim</name>
        </component>
        <component>
          <package>velma_sim_gazebo</package>
          <type>FtSensorGazebo</type>
          <name>LeftFtSensor</name>
        </component>
        <component>
          <package>velma_sim_gazebo</package>
          <type>FtSensorGazebo</type>
          <name>RightFtSensor</name>
        </component>
        <component>
          <package>velma_sim_gazebo</package>
          <type>BarrettHandGazebo</type>
          <name>RightHand</name>
        </component>
        <component>
          <package>velma_sim_gazebo</package>
          <type>BarrettTactileGazebo</type>
          <name>RightHandTactile</name>
        </component>
        <component>
          <package>velma_sim_gazebo</package>
          <type>BarrettHandGazebo</type>
          <name>LeftHand</name>
        </component>
        <component>
          <package>velma_sim_gazebo</package>
          <type>OptoforceGazebo</type>
          <name>LeftHandOptoforce</name>
        </component>
        <robotNamespace>/</robotNamespace>
      </plugin>
      <pose frame=''>0 0 0 0 -0 0</pose>
    </model>
    <model name='table'>
      <static>1</static>
      <link name='link'>
        <collision name='surface'>
          <pose frame=''>0 0 1 0 -0 0</pose>
          <geometry>
            <box>
              <size>1.5 0.8 0.03</size>
            </box>
          </geometry>
          <surface>
            <friction>
              <ode>
                <mu>0.6</mu>
                <mu2>0.6</mu2>
              </ode>
            </friction>
            <contact/>
          </surface>
          <max_contacts>10</max_contacts>
        </collision>
        <visual name='visual1'>
          <pose frame=''>0 0 1 0 -0 0</pose>
          <geometry>
            <box>
              <size>1.5 0.8 0.03</size>
            </box>
          </geometry>
          <material>
            <script>
              <uri>file://media/materials/scripts/gazebo.material</uri>
              <name>Gazebo/Wood</name>
            </script>
          </material>
        </visual>
        <collision name='front_left_leg'>
          <pose frame=''>0.68 0.38 0.5 0 -0 0</pose>
          <geometry>
            <cylinder>
              <radius>0.02</radius>
              <length>1</length>
            </cylinder>
          </geometry>
          <max_contacts>10</max_contacts>
          <surface>
            <contact/>
            <friction>
              <ode/>
            </friction>
          </surface>
        </collision>
        <visual name='front_left_leg'>
          <pose frame=''>0.68 0.38 0.5 0 -0 0</pose>
          <geometry>
            <cylinder>
              <radius>0.02</radius>
              <length>1</length>
            </cylinder>
          </geometry>
          <material>
            <script>
              <uri>file://media/materials/scripts/gazebo.material</uri>
              <name>Gazebo/Grey</name>
            </script>
          </material>
        </visual>
        <collision name='front_right_leg'>
          <pose frame=''>0.68 -0.38 0.5 0 -0 0</pose>
          <geometry>
            <cylinder>
              <radius>0.02</radius>
              <length>1</length>
            </cylinder>
          </geometry>
          <max_contacts>10</max_contacts>
          <surface>
            <contact/>
            <friction>
              <ode/>
            </friction>
          </surface>
        </collision>
        <visual name='front_right_leg'>
          <pose frame=''>0.68 -0.38 0.5 0 -0 0</pose>
          <geometry>
            <cylinder>
              <radius>0.02</radius>
              <length>1</length>
            </cylinder>
          </geometry>
          <material>
            <script>
              <uri>file://media/materials/scripts/gazebo.material</uri>
              <name>Gazebo/Grey</name>
            </script>
          </material>
        </visual>
        <collision name='back_right_leg'>
          <pose frame=''>-0.68 -0.38 0.5 0 -0 0</pose>
          <geometry>
            <cylinder>
              <radius>0.02</radius>
              <length>1</length>
            </cylinder>
          </geometry>
          <max_contacts>10</max_contacts>
          <surface>
            <contact/>
            <friction>
              <ode/>
            </friction>
          </surface>
        </collision>
        <visual name='back_right_leg'>
          <pose frame=''>-0.68 -0.38 0.5 0 -0 0</pose>
          <geometry>
            <cylinder>
              <radius>0.02</radius>
              <length>1</length>
            </cylinder>
          </geometry>
          <material>
            <script>
              <uri>file://media/materials/scripts/gazebo.material</uri>
              <name>Gazebo/Grey</name>
            </script>
          </material>
        </visual>
        <collision name='back_left_leg'>
          <pose frame=''>-0.68 0.38 0.5 0 -0 0</pose>
          <geometry>
            <cylinder>
              <radius>0.02</radius>
              <length>1</length>
            </cylinder>
          </geometry>
          <max_contacts>10</max_contacts>
          <surface>
            <contact/>
            <friction>
              <ode/>
            </friction>
          </surface>
        </collision>
        <visual name='back_left_leg'>
          <pose frame=''>-0.68 0.38 0.5 0 -0 0</pose>
          <geometry>
            <cylinder>
              <radius>0.02</radius>
              <length>1</length>
            </cylinder>
          </geometry>
          <material>
            <script>
              <uri>file://media/materials/scripts/gazebo.material</uri>
              <name>Gazebo/Grey</name>
            </script>
          </material>
        </visual>
        <self_collide>0</self_collide>
        <enable_wind>0</enable_wind>
        <gravity>1</gravity>
      </link>
      <pose frame=''>0.038829 -1.11064 0 0 -0 0</pose>
    </model>
    <model name='beer'>
      <link name='link'>
        <pose frame=''>0 0 0.115 0 -0 0</pose>
        <inertial>
          <mass>0.39</mass>
          <inertia>
            <ixx>0.00058</ixx>
            <ixy>0</ixy>
            <ixz>0</ixz>
            <iyy>0.00058</iyy>
            <iyz>0</iyz>
            <izz>0.00019</izz>
          </inertia>
          <pose frame=''>0 0 0 0 -0 0</pose>
        </inertial>
        <collision name='collision'>
          <geometry>
            <cylinder>
              <radius>0.055</radius>
              <length>0.23</length>
            </cylinder>
          </geometry>
          <max_contacts>10</max_contacts>
          <surface>
            <contact/>
            <friction>
              <ode/>
            </friction>
          </surface>
        </collision>
        <visual name='visual'>
          <geometry>
            <cylinder>
              <radius>0.055</radius>
              <length>0.23</length>
            </cylinder>
          </geometry>
          <material>
            <script>
              <uri>model://beer/materials/scripts</uri>
              <uri>model://beer/materials/textures</uri>
              <name>Beer/Diffuse</name>
            </script>
          </material>
        </visual>
        <self_collide>0</self_collide>
        <enable_wind>0</enable_wind>
        <gravity>1</gravity>
      </link>
      <pose frame=''>0.286187 -1.2253 0 0 -0 0</pose>
    </model>
    <model name='table_0'>
      <static>1</static>
      <link name='link'>
        <collision name='surface'>
          <pose frame=''>0 0 1 0 -0 0</pose>
          <geometry>
            <box>
              <size>1.5 0.8 0.03</size>
            </box>
          </geometry>
          <surface>
            <friction>
              <ode>
                <mu>0.6</mu>
                <mu2>0.6</mu2>
              </ode>
            </friction>
            <contact/>
          </surface>
          <max_contacts>10</max_contacts>
        </collision>
        <visual name='visual1'>
          <pose frame=''>0 0 1 0 -0 0</pose>
          <geometry>
            <box>
              <size>1.5 0.8 0.03</size>
            </box>
          </geometry>
          <material>
            <script>
              <uri>file://media/materials/scripts/gazebo.material</uri>
              <name>Gazebo/Wood</name>
            </script>
          </material>
        </visual>
        <collision name='front_left_leg'>
          <pose frame=''>0.68 0.38 0.5 0 -0 0</pose>
          <geometry>
            <cylinder>
              <radius>0.02</radius>
              <length>1</length>
            </cylinder>
          </geometry>
          <max_contacts>10</max_contacts>
          <surface>
            <contact/>
            <friction>
              <ode/>
            </friction>
          </surface>
        </collision>
        <visual name='front_left_leg'>
          <pose frame=''>0.68 0.38 0.5 0 -0 0</pose>
          <geometry>
            <cylinder>
              <radius>0.02</radius>
              <length>1</length>
            </cylinder>
          </geometry>
          <material>
            <script>
              <uri>file://media/materials/scripts/gazebo.material</uri>
              <name>Gazebo/Grey</name>
            </script>
          </material>
        </visual>
        <collision name='front_right_leg'>
          <pose frame=''>0.68 -0.38 0.5 0 -0 0</pose>
          <geometry>
            <cylinder>
              <radius>0.02</radius>
              <length>1</length>
            </cylinder>
          </geometry>
          <max_contacts>10</max_contacts>
          <surface>
            <contact/>
            <friction>
              <ode/>
            </friction>
          </surface>
        </collision>
        <visual name='front_right_leg'>
          <pose frame=''>0.68 -0.38 0.5 0 -0 0</pose>
          <geometry>
            <cylinder>
              <radius>0.02</radius>
              <length>1</length>
            </cylinder>
          </geometry>
          <material>
            <script>
              <uri>file://media/materials/scripts/gazebo.material</uri>
              <name>Gazebo/Grey</name>
            </script>
          </material>
        </visual>
        <collision name='back_right_leg'>
          <pose frame=''>-0.68 -0.38 0.5 0 -0 0</pose>
          <geometry>
            <cylinder>
              <radius>0.02</radius>
              <length>1</length>
            </cylinder>
          </geometry>
          <max_contacts>10</max_contacts>
          <surface>
            <contact/>
            <friction>
              <ode/>
            </friction>
          </surface>
        </collision>
        <visual name='back_right_leg'>
          <pose frame=''>-0.68 -0.38 0.5 0 -0 0</pose>
          <geometry>
            <cylinder>
              <radius>0.02</radius>
              <length>1</length>
            </cylinder>
          </geometry>
          <material>
            <script>
              <uri>file://media/materials/scripts/gazebo.material</uri>
              <name>Gazebo/Grey</name>
            </script>
          </material>
        </visual>
        <collision name='back_left_leg'>
          <pose frame=''>-0.68 0.38 0.5 0 -0 0</pose>
          <geometry>
            <cylinder>
              <radius>0.02</radius>
              <length>1</length>
            </cylinder>
          </geometry>
          <max_contacts>10</max_contacts>
          <surface>
            <contact/>
            <friction>
              <ode/>
            </friction>
          </surface>
        </collision>
        <visual name='back_left_leg'>
          <pose frame=''>-0.68 0.38 0.5 0 -0 0</pose>
          <geometry>
            <cylinder>
              <radius>0.02</radius>
              <length>1</length>
            </cylinder>
          </geometry>
          <material>
            <script>
              <uri>file://media/materials/scripts/gazebo.material</uri>
              <name>Gazebo/Grey</name>
            </script>
          </material>
        </visual>
        <self_collide>0</self_collide>
        <enable_wind>0</enable_wind>
        <gravity>1</gravity>
      </link>
      <pose frame=''>1.59892 -0.060544 0 0 -0 0</pose>
    </model>
    <state world_name='default'>
      <sim_time>154 434000000</sim_time>
      <real_time>0 0</real_time>
      <wall_time>1541408355 757810854</wall_time>
      <iterations>76767</iterations>
      <model name='beer'>
        <pose frame=''>-0.320617 -0.862807 1.015 2e-06 -2e-06 -0.000818</pose>
        <scale>1 1 1</scale>
        <link name='link'>
          <pose frame=''>-0.320618 -0.862807 1.13 2e-06 -2e-06 -0.000818</pose>
          <velocity>2e-06 4e-06 5e-06 -3.1e-05 2.1e-05 -2e-06</velocity>
          <acceleration>0 0 0 -0 -0 -0</acceleration>
          <wrench>0 0 0 0 -0 0</wrench>
        </link>
      </model>
      <model name='ground_plane'>
        <pose frame=''>0 0 0 0 -0 0</pose>
        <scale>1 1 1</scale>
        <link name='link'>
          <pose frame=''>0 0 0 0 -0 0</pose>
          <velocity>0 0 0 0 -0 0</velocity>
          <acceleration>0 0 0 0 -0 0</acceleration>
          <wrench>0 0 0 0 -0 0</wrench>
        </link>
      </model>
      <model name='table'>
        <pose frame=''>0.038829 -1.11064 0 0 -0 0</pose>
        <scale>1 1 1</scale>
        <link name='link'>
          <pose frame=''>0.038829 -1.11064 0 0 -0 0</pose>
          <velocity>0 0 0 0 -0 0</velocity>
          <acceleration>0 0 0 0 -0 0</acceleration>
          <wrench>0 0 0 0 -0 0</wrench>
        </link>
      </model>
      <model name='table_0'>
        <pose frame=''>1.02702 0.591095 0 0 -0 1.59992</pose>
        <scale>1 1 1</scale>
        <link name='link'>
          <pose frame=''>1.02702 0.591095 0 0 -0 1.59992</pose>
          <velocity>0 0 0 0 -0 0</velocity>
          <acceleration>0 0 0 0 -0 0</acceleration>
          <wrench>0 0 0 0 -0 0</wrench>
        </link>
      </model>
      <model name='velma'>
        <pose frame=''>0 0 0 0 -0 0</pose>
        <scale>1 1 1</scale>
        <link name='head_pan_link'>
          <pose frame=''>0.020441 -0.000423 1.4987 0.000403 -0.006272 -0.048952</pose>
          <velocity>0 0 -0 0 -0 2e-06</velocity>
          <acceleration>0 0 0 0 -0 0</acceleration>
          <wrench>0 0 0 0 -0 0</wrench>
        </link>
        <link name='head_tilt_link'>
          <pose frame=''>0.02014 -0.000427 1.5467 1.5704 -0.006272 -0.048952</pose>
          <velocity>0 0 0 0 -0 2e-06</velocity>
          <acceleration>0 0 0 0 -0 0</acceleration>
          <wrench>0 0 0 0 -0 0</wrench>
        </link>
        <link name='left_FtSensorLink'>
          <pose frame=''>0.025799 0.432328 0.630205 2.89774 -0.55794 3.03191</pose>
          <velocity>-4.5e-05 -8.6e-05 -0.000257 -0.000291 -0.002572 0.000549</velocity>
          <acceleration>0 0 0 0 -0 0</acceleration>
          <wrench>0 0 0 0 -0 0</wrench>
        </link>
        <link name='left_HandFingerOneKnuckleOneLink'>
          <pose frame=''>0.018382 0.447428 0.568576 2.57714 0.226784 -1.77858</pose>
          <velocity>0.000105 -0.000108 -0.00028 -0.00037 -0.002524 0.000416</velocity>
          <acceleration>-0 0 0 1e-06 -0 0</acceleration>
          <wrench>-0 0 0 0 -0 0</wrench>
        </link>
        <link name='left_HandFingerOneKnuckleThreeLink'>
          <pose frame=''>-0.015022 0.338746 0.525807 0.722787 0.802318 -2.32107</pose>
          <velocity>0.000256 -0.000136 -0.000328 -0.000312 -0.002528 0.000381</velocity>
          <acceleration>0 0 0 2e-06 0 -1e-06</acceleration>
          <wrench>0 0 0 0 -0 0</wrench>
        </link>
        <link name='left_HandFingerOneKnuckleThreeOptoforceSensor'>
          <pose frame=''>-0.040481 0.322215 0.486019 -3.09966 0.548323 -0.066373</pose>
          <velocity>0.000363 -0.000158 -0.000387 -0.000312 -0.002528 0.000381</velocity>
          <acceleration>0 0 -0 -1e-06 -0 -1e-06</acceleration>
          <wrench>0 0 -0 0 -0 0</wrench>
        </link>
        <link name='left_HandFingerOneKnuckleTwoLink'>
          <pose frame=''>0.000291 0.404675 0.543664 1.00143 0.257952 -1.79902</pose>
          <velocity>0.000186 -0.000125 -0.00031 -0.000319 -0.002527 0.000386</velocity>
          <acceleration>0 0 0 2e-06 -0 0</acceleration>
          <wrench>0 0 0 0 -0 0</wrench>
        </link>
        <link name='left_HandFingerThreeKnuckleThreeLink'>
          <pose frame=''>0.015944 0.569495 0.590447 2.1885 0.417402 1.74152</pose>
          <velocity>-2.1e-05 -0.000102 -0.000326 -0.000352 -0.002565 0.000588</velocity>
          <acceleration>0 0 0 -1e-06 0 2e-06</acceleration>
          <wrench>0 0 0 0 -0 0</wrench>
        </link>
        <link name='left_HandFingerThreeKnuckleThreeOptoforceSensor'>
          <pose frame=''>0.003185 0.609659 0.563077 2.67987 -0.557941 3.03191</pose>
          <velocity>2.6e-05 -0.000119 -0.000373 -0.000352 -0.002565 0.000588</velocity>
          <acceleration>0 0 0 -2e-06 -0 -0</acceleration>
          <wrench>0 0 0 0 -0 0</wrench>
        </link>
        <link name='left_HandFingerThreeKnuckleTwoLink'>
          <pose frame=''>0.000951 0.502194 0.578372 2.13826 -0.173361 1.3516</pose>
          <velocity>5e-05 -0.000115 -0.000341 -0.000346 -0.002566 0.000584</velocity>
          <acceleration>0 0 0 2e-06 -0 0</acceleration>
          <wrench>0 0 0 0 -0 0</wrench>
        </link>
        <link name='left_HandFingerTwoKnuckleOneLink'>
          <pose frame=''>-0.02373 0.452066 0.595016 2.57026 0.206859 -1.81055</pose>
          <velocity>3.4e-05 -0.000123 -0.00039 -0.000288 -0.002574 0.000555</velocity>
          <acceleration>-0 0 0 1e-06 -0 0</acceleration>
          <wrench>-0 0 0 0 -0 0</wrench>
        </link>
        <link name='left_HandFingerTwoKnuckleThreeLink'>
          <pose frame=''>-0.060893 0.343709 0.554593 0.72891 0.781989 -2.34738</pose>
          <velocity>0.000197 -0.000154 -0.000458 -0.000235 -0.00258 0.000522</velocity>
          <acceleration>0 0 0 2e-06 0 -1e-06</acceleration>
          <wrench>0 0 0 0 -0 0</wrench>
        </link>
        <link name='left_HandFingerTwoKnuckleThreeOptoforceSensor'>
          <pose frame=''>-0.087309 0.327279 0.515349 -3.12146 0.557688 -0.108491</pose>
          <velocity>0.000306 -0.000177 -0.000522 -0.000235 -0.00258 0.000522</velocity>
          <acceleration>0 0 -0 -1e-06 -0 -1e-06</acceleration>
          <wrench>0 0 -0 0 -0 0</wrench>
        </link>
        <link name='left_HandFingerTwoKnuckleTwoLink'>
          <pose frame=''>-0.043391 0.409451 0.571077 0.994953 0.23772 -1.83099</pose>
          <velocity>0.00012 -0.000141 -0.000428 -0.000238 -0.002579 0.000524</velocity>
          <acceleration>0 0 0 2e-06 0 -1e-06</acceleration>
          <wrench>0 0 0 0 -0 0</wrench>
        </link>
        <link name='left_arm_1_link'>
          <pose frame=''>1e-06 0.095452 1.32835 0.473406 0.974256 2.12521</pose>
          <velocity>-0 0 -0 0 0.000181 0.000107</velocity>
          <acceleration>0 0 0 0 -0 0</acceleration>
          <wrench>0 0 0 0 -0 0</wrench>
        </link>
        <link name='left_arm_2_link'>
          <pose frame=''>2e-06 0.26909 1.4286 2.86983 0.303907 -1.50042</pose>
          <velocity>-1e-06 0 -0 -9.9e-05 0.000165 0.000133</velocity>
          <acceleration>0 0 0 0 -0 0</acceleration>
          <wrench>0 0 0 0 -0 0</wrench>
        </link>
        <link name='left_arm_3_link'>
          <pose frame=''>-0.057605 0.322826 1.24477 -2.92515 0.344883 -0.173991</pose>
          <velocity>-3.8e-05 -2.6e-05 4e-06 -0.000118 0.000183 7.4e-05</velocity>
          <acceleration>0 0 -0 0 -0 0</acceleration>
          <wrench>0 0 -0 0 -0 0</wrench>
        </link>
        <link name='left_arm_4_link'>
          <pose frame=''>-0.115213 0.376562 1.06094 -2.9112 -0.484124 -0.356936</pose>
          <velocity>-7.6e-05 -5.2e-05 8e-06 -2e-05 0.000568 0.000156</velocity>
          <acceleration>0 0 0 0 -0 0</acceleration>
          <wrench>0 0 0 0 -0 0</wrench>
        </link>
        <link name='left_arm_5_link'>
          <pose frame=''>-0.01434 0.38769 0.888599 -2.91467 -0.485653 -0.34951</pose>
          <velocity>-0.000175 -3.9e-05 -4.9e-05 -0.001152 0.000443 0.002091</velocity>
          <acceleration>0 0 0 -1e-06 0 0</acceleration>
          <wrench>0 0 0 0 -0 0</wrench>
        </link>
        <link name='left_arm_6_link'>
          <pose frame=''>0.081489 0.398262 0.724876 -2.78267 -0.968615 -0.542</pose>
          <velocity>-0.00027 -2.8e-05 -0.000104 -0.001851 -0.002385 0.001499</velocity>
          <acceleration>0 -0 0 0 -0 0</acceleration>
          <wrench>0 -0 0 0 -0 0</wrench>
        </link>
        <link name='left_arm_7_link'>
          <pose frame=''>0.147181 0.390688 0.683509 -2.7769 -0.96711 -0.549008</pose>
          <velocity>-0.00016 -6e-06 6.7e-05 -0.000305 -0.002564 0.000526</velocity>
          <acceleration>0 -0 0 0 -0 1e-06</acceleration>
          <wrench>0 -0 0 0 -0 0</wrench>
        </link>
        <link name='right_FtSensorLink'>
          <pose frame=''>0.025731 -0.432533 0.630251 -2.89735 -0.558376 -3.03172</pose>
          <velocity>-6.3e-05 2.9e-05 -0.000239 6.1e-05 -0.002409 -0.000442</velocity>
          <acceleration>-0 0 0 0 -0 0</acceleration>
          <wrench>-0 0 0 0 -0 0</wrench>
        </link>
        <link name='right_HandFingerOneKnuckleOneLink'>
          <pose frame=''>-0.023804 -0.452303 0.595088 -2.56976 0.207093 1.8111</pose>
          <velocity>1.3e-05 5.3e-05 -0.000359 5.8e-05 -0.002411 -0.000447</velocity>
          <acceleration>0 0 -0 -1e-06 -0 0</acceleration>
          <wrench>0 0 -0 0 -0 0</wrench>
        </link>
        <link name='right_HandFingerOneKnuckleThreeLink'>
          <pose frame=''>-0.060942 -0.343914 0.554799 2.41039 0.779197 2.34403</pose>
          <velocity>0.000157 7.1e-05 -0.000445 1.5e-05 -0.002416 -0.00042</velocity>
          <acceleration>0 0 0 -1e-06 -0 1e-06</acceleration>
          <wrench>0 0 0 0 -0 0</wrench>
        </link>
        <link name='right_HandFingerOneKnuckleTwoLink'>
          <pose frame=''>-0.043494 -0.409705 0.571143 2.14678 0.23566 1.83003</pose>
          <velocity>8.9e-05 6.3e-05 -0.000404 1.8e-05 -0.002415 -0.000422</velocity>
          <acceleration>0 0 0 -2e-06 0 1e-06</acceleration>
          <wrench>0 0 0 0 -0 0</wrench>
        </link>
        <link name='right_HandFingerThreeKnuckleThreeLink'>
          <pose frame=''>0.016027 -0.569659 0.590738 0.95408 0.412651 -1.73793</pose>
          <velocity>-3.1e-05 3.4e-05 -0.000274 0.000112 -0.002404 -0.000474</velocity>
          <acceleration>0 -0 0 1e-06 -0 -1e-06</acceleration>
          <wrench>0 -0 0 0 -0 0</wrench>
        </link>
        <link name='right_HandFingerThreeKnuckleTwoLink'>
          <pose frame=''>0.000889 -0.502428 0.578454 1.00254 -0.176406 -1.34933</pose>
          <velocity>3.1e-05 4.3e-05 -0.000303 0.000107 -0.002404 -0.000471</velocity>
          <acceleration>0 0 0 -2e-06 0 1e-06</acceleration>
          <wrench>0 0 0 0 -0 0</wrench>
        </link>
        <link name='right_HandFingerTwoKnuckleOneLink'>
          <pose frame=''>0.018295 -0.447659 0.56863 -2.57651 0.226639 1.77977</pose>
          <velocity>7.8e-05 3.6e-05 -0.000258 0.000132 -0.002366 -0.000322</velocity>
          <acceleration>0 0 -0 -1e-06 -0 0</acceleration>
          <wrench>0 0 -0 0 -0 0</wrench>
        </link>
        <link name='right_HandFingerTwoKnuckleThreeLink'>
          <pose frame=''>-0.015159 -0.338948 0.526039 2.41667 0.799492 2.31871</pose>
          <velocity>0.000213 5.1e-05 -0.000325 8.7e-05 -0.002369 -0.000295</velocity>
          <acceleration>0 0 0 -2e-06 0 1e-06</acceleration>
          <wrench>0 0 0 0 -0 0</wrench>
        </link>
        <link name='right_HandFingerTwoKnuckleTwoLink'>
          <pose frame=''>0.000143 -0.404925 0.54373 2.1404 0.255489 1.7987</pose>
          <velocity>0.000151 4.5e-05 -0.000295 9.1e-05 -0.002369 -0.000298</velocity>
          <acceleration>0 0 0 -2e-06 0 1e-06</acceleration>
          <wrench>0 0 0 0 -0 0</wrench>
        </link>
        <link name='right_arm_1_link'>
          <pose frame=''>-1e-06 -0.095452 1.32835 0.473419 -0.974254 1.01636</pose>
          <velocity>0 -0 -0 0 0.000181 -0.000102</velocity>
          <acceleration>0 0 0 0 -0 0</acceleration>
          <wrench>0 0 0 0 -0 0</wrench>
        </link>
        <link name='right_arm_2_link'>
          <pose frame=''>-2e-06 -0.26909 1.4286 2.86981 -0.304091 -1.64114</pose>
          <velocity>1e-06 -0 -0 6.6e-05 0.000171 -0.00012</velocity>
          <acceleration>-0 0 0 -0 -0 -0</acceleration>
          <wrench>-0 0 0 0 -0 0</wrench>
        </link>
        <link name='right_arm_3_link'>
          <pose frame=''>-0.057614 -0.322861 1.24478 -2.92494 -0.344938 -2.96769</pose>
          <velocity>-3.7e-05 1.9e-05 6e-06 7.9e-05 0.000183 -7.6e-05</velocity>
          <acceleration>-0 0 0 0 -0 0</acceleration>
          <wrench>-0 0 0 0 -0 0</wrench>
        </link>
        <link name='right_arm_4_link'>
          <pose frame=''>-0.115226 -0.376632 1.06096 -2.91101 0.483967 -2.7846</pose>
          <velocity>-7.5e-05 3.8e-05 1.3e-05 -2.3e-05 0.000588 -0.000162</velocity>
          <acceleration>0 0 -0 0 -0 0</acceleration>
          <wrench>0 0 -0 0 -0 0</wrench>
        </link>
        <link name='right_arm_5_link'>
          <pose frame=''>-0.01437 -0.3878 0.888616 -2.91439 0.485461 -2.79185</pose>
          <velocity>-0.000178 1.8e-05 -4.6e-05 0.001066 0.000468 -0.002023</velocity>
          <acceleration>0 0 -0 1e-06 -0 0</acceleration>
          <wrench>0 0 -0 0 -0 0</wrench>
        </link>
        <link name='right_arm_6_link'>
          <pose frame=''>0.081444 -0.398409 0.724887 -2.78244 0.968151 -2.59935</pose>
          <velocity>-0.000276 -2e-06 -0.000103 0.001728 -0.002211 -0.001463</velocity>
          <acceleration>0 0 -0 0 -0 0</acceleration>
          <wrench>0 0 -0 0 -0 0</wrench>
        </link>
        <link name='right_arm_7_link'>
          <pose frame=''>0.147122 -0.390846 0.683495 -2.77642 0.96658 -2.59204</pose>
          <velocity>-0.000174 -2.6e-05 5.6e-05 7.4e-05 -0.002401 -0.00042</velocity>
          <acceleration>0 0 -0 0 0 -1e-06</acceleration>
          <wrench>0 0 -0 0 -0 0</wrench>
        </link>
        <link name='torso_base'>
          <pose frame=''>0 0 0 0 -0 0</pose>
          <velocity>0 0 0 0 -0 0</velocity>
          <acceleration>0 0 0 0 -0 0</acceleration>
          <wrench>0 0 0 0 -0 0</wrench>
        </link>
        <link name='torso_link0'>
          <pose frame=''>0 0 0.1 0 0 -7e-06</pose>
          <velocity>0 0 0 0 -0 2e-06</velocity>
          <acceleration>0 0 0 0 -0 0</acceleration>
          <wrench>0 0 0 0 -0 0</wrench>
        </link>
      </model>
      <light name='sun'>
        <pose frame=''>0 0 10 0 -0 0</pose>
      </light>
    </state>
    <gui fullscreen='0'>
      <camera name='user_camera'>
        <pose frame=''>3.3827 -2.31354 4.78028 0 0.951643 2.61619</pose>
        <view_controller>orbit</view_controller>
        <projection_type>perspective</projection_type>
      </camera>
    </gui>
  </world>
</sdf>
